Workbook

Sheet Summary
A1: Personal Ledger Summary
A2: Workbook year: 2026
A4: Annual Overview
A5: Month | B5: Income | C5: Expenses | D5: Existing Savings | E5: Transfers | F5: Net Cash Flow | G5: Current Balance
A6: Jan 2026 | B6: ='Jan 2026'!$B$5 | C6: ='Jan 2026'!$B$6 | D6: ='Jan 2026'!$B$7 | E6: ='Jan 2026'!$B$8 | F6: ='Jan 2026'!$B$9 | G6: ='Jan 2026'!$B$10 -> 0
A7: Feb 2026 | B7: ='Feb 2026'!$B$5 | C7: ='Feb 2026'!$B$6 | D7: ='Feb 2026'!$B$7 | E7: ='Feb 2026'!$B$8 | F7: ='Feb 2026'!$B$9 | G7: ='Feb 2026'!$B$10 -> 0
A8: Mar 2026 | B8: ='Mar 2026'!$B$5 | C8: ='Mar 2026'!$B$6 | D8: ='Mar 2026'!$B$7 | E8: ='Mar 2026'!$B$8 | F8: ='Mar 2026'!$B$9 | G8: ='Mar 2026'!$B$10 -> 0
A9: Apr 2026 | B9: ='Apr 2026'!$B$5 | C9: ='Apr 2026'!$B$6 | D9: ='Apr 2026'!$B$7 | E9: ='Apr 2026'!$B$8 | F9: ='Apr 2026'!$B$9 | G9: ='Apr 2026'!$B$10 -> 0
A10: May 2026 | B10: ='May 2026'!$B$5 | C10: ='May 2026'!$B$6 | D10: ='May 2026'!$B$7 | E10: ='May 2026'!$B$8 | F10: ='May 2026'!$B$9 | G10: ='May 2026'!$B$10 -> 0
A11: Jun 2026 | B11: ='Jun 2026'!$B$5 | C11: ='Jun 2026'!$B$6 | D11: ='Jun 2026'!$B$7 | E11: ='Jun 2026'!$B$8 | F11: ='Jun 2026'!$B$9 | G11: ='Jun 2026'!$B$10 -> 0
A12: Jul 2026 | B12: ='Jul 2026'!$B$5 | C12: ='Jul 2026'!$B$6 | D12: ='Jul 2026'!$B$7 | E12: ='Jul 2026'!$B$8 | F12: ='Jul 2026'!$B$9 | G12: ='Jul 2026'!$B$10 -> 0
A13: Aug 2026 | B13: ='Aug 2026'!$B$5 -> 4988 | C13: ='Aug 2026'!$B$6 -> 2741.56 | D13: ='Aug 2026'!$B$7 -> 7300 | E13: ='Aug 2026'!$B$8 -> 1700 | F13: ='Aug 2026'!$B$9 -> 2246.44 | G13: ='Aug 2026'!$B$10 -> 8242.24
A14: Sep 2026 | B14: ='Sep 2026'!$B$5 -> 3126 | C14: ='Sep 2026'!$B$6 -> 2841.18 | D14: ='Sep 2026'!$B$7 -> 0 | E14: ='Sep 2026'!$B$8 -> 106 | F14: ='Sep 2026'!$B$9 -> 284.82 | G14: ='Sep 2026'!$B$10 -> 9127.06
A15: Oct 2026 | B15: ='Oct 2026'!$B$5 -> 0 | C15: ='Oct 2026'!$B$6 -> 1536.47 | D15: ='Oct 2026'!$B$7 -> 0 | E15: ='Oct 2026'!$B$8 -> 0 | F15: ='Oct 2026'!$B$9 -> -1536.47 | G15: ='Oct 2026'!$B$10 -> 7590.59
A16: Nov 2026 | B16: ='Nov 2026'!$B$5 | C16: ='Nov 2026'!$B$6 | D16: ='Nov 2026'!$B$7 | E16: ='Nov 2026'!$B$8 | F16: ='Nov 2026'!$B$9 | G16: ='Nov 2026'!$B$10 -> 0
A17: Dec 2026 | B17: ='Dec 2026'!$B$5 | C17: ='Dec 2026'!$B$6 | D17: ='Dec 2026'!$B$7 | E17: ='Dec 2026'!$B$8 | F17: ='Dec 2026'!$B$9 | G17: ='Dec 2026'!$B$10 -> 0
A18: Total | B18: =SUM(B6:B17) -> 8114 | C18: =SUM(C6:C17) -> 7119.21 | D18: =SUM(D6:D17) -> 7300 | E18: =SUM(E6:E17) -> 1806 | F18: =SUM(F6:F17) -> 994.79 | G18: =LOOKUP(2,1/(G6:G17<>0),G6:G17) -> 7590.59
A20: Annual Category Summary
A21: Category | B21: Expenses | C21: Income | D21: Existing Savings | E21: Net
A22: Housing | B22: =SUMIFS('Jan 2026'!$J$29:$J$528,'Jan 2026'!$E$29:$E$528,$A22,'Jan 2026'!$I$29:$I$528,"Expense")+SUMIFS('Feb 2026'!$J$29:$J$528,'Feb 2026'!$E$29:$E$528,$A22,'Feb 2026'!$I$29:$I$528,"Expense")+SUMIFS('Mar 2026'!$J$29:$J$528,'Mar 2026'!$E$29:$E$528,$A22,'Mar 2026'!$I$29:$I$528,"Expense")+SUMIFS('Apr 2026'!$J$29:$J$528,'Apr 2026'!$E$29:$E$528,$A22,'Apr 2026'!$I$29:$I$528,"Expense")+SUMIFS('May 2026'!$J$29:$J$528,'May 2026'!$E$29:$E$528,$A22,'May 2026'!$I$29:$I$528,"Expense")+SUMIFS('Jun 2026'!$J$29:$J$528,'Jun 2026'!$E$29:$E$528,$A22,'Jun 2026'!$I$29:$I$528,"Expense")+SUMIFS('Jul 2026'!$J$29:$J$528,'Jul 2026'!$E$29:$E$528,$A22,'Jul 2026'!$I$29:$I$528,"Expense")+SUMIFS('Aug 2026'!$J$29:$J$528,'Aug 2026'!$E$29:$E$528,$A22,'Aug 2026'!$I$29:$I$528,"Expense")+SUMIFS('Sep 2026'!$J$29:$J$528,'Sep 2026'!$E$29:$E$528,$A22,'Sep 2026'!$I$29:$I$528,"Expense")+SUMIFS('Oct 2026'!$J$29:$J$528,'Oct 2026'!$E$29:$E$528,$A22,'Oct 2026'!$I$29:$I$528,"Expense")+SUMIFS('Nov 2026'!$J$29:$J$528,'Nov 2026'!$E$29:$E$528,$A22,'Nov 2026'!$I$29:$I$528,"Expense")+SUMIFS('Dec 2026'!$J$29:$J$528,'Dec 2026'!$E$29:$E$528,$A22,'Dec 2026'!$I$29:$I$528,"Expense") -> 3300 | C22: =SUMIFS('Jan 2026'!$J$29:$J$528,'Jan 2026'!$E$29:$E$528,$A22,'Jan 2026'!$I$29:$I$528,"Income")+SUMIFS('Feb 2026'!$J$29:$J$528,'Feb 2026'!$E$29:$E$528,$A22,'Feb 2026'!$I$29:$I$528,"Income")+SUMIFS('Mar 2026'!$J$29:$J$528,'Mar 2026'!$E$29:$E$528,$A22,'Mar 2026'!$I$29:$I$528,"Income")+SUMIFS('Apr 2026'!$J$29:$J$528,'Apr 2026'!$E$29:$E$528,$A22,'Apr 2026'!$I$29:$I$528,"Income")+SUMIFS('May 2026'!$J$29:$J$528,'May 2026'!$E$29:$E$528,$A22,'May 2026'!$I$29:$I$528,"Income")+SUMIFS('Jun 2026'!$J$29:$J$528,'Jun 2026'!$E$29:$E$528,$A22,'Jun 2026'!$I$29:$I$528,"Income")+SUMIFS('Jul 2026'!$J$29:$J$528,'Jul 2026'!$E$29:$E$528,$A22,'Jul 2026'!$I$29:$I$528,"Income")+SUMIFS('Aug 2026'!$J$29:$J$528,'Aug 2026'!$E$29:$E$528,$A22,'Aug 2026'!$I$29:$I$528,"Income")+SUMIFS('Sep 2026'!$J$29:$J$528,'Sep 2026'!$E$29:$E$528,$A22,'Sep 2026'!$I$29:$I$528,"Income")+SUMIFS('Oct 2026'!$J$29:$J$528,'Oct 2026'!$E$29:$E$528,$A22,'Oct 2026'!$I$29:$I$528,"Income")+SUMIFS('Nov 2026'!$J$29:$J$528,'Nov 2026'!$E$29:$E$528,$A22,'Nov 2026'!$I$29:$I$528,"Income")+SUMIFS('Dec 2026'!$J$29:$J$528,'Dec 2026'!$E$29:$E$528,$A22,'Dec 2026'!$I$29:$I$528,"Income") -> 0 | D22: =SUMIFS('Jan 2026'!$J$29:$J$528,'Jan 2026'!$E$29:$E$528,$A22,'Jan 2026'!$I$29:$I$528,"Opening Balance")+SUMIFS('Feb 2026'!$J$29:$J$528,'Feb 2026'!$E$29:$E$528,$A22,'Feb 2026'!$I$29:$I$528,"Opening Balance")+SUMIFS('Mar 2026'!$J$29:$J$528,'Mar 2026'!$E$29:$E$528,$A22,'Mar 2026'!$I$29:$I$528,"Opening Balance")+SUMIFS('Apr 2026'!$J$29:$J$528,'Apr 2026'!$E$29:$E$528,$A22,'Apr 2026'!$I$29:$I$528,"Opening Balance")+SUMIFS('May 2026'!$J$29:$J$528,'May 2026'!$E$29:$E$528,$A22,'May 2026'!$I$29:$I$528,"Opening Balance")+SUMIFS('Jun 2026'!$J$29:$J$528,'Jun 2026'!$E$29:$E$528,$A22,'Jun 2026'!$I$29:$I$528,"Opening Balance")+SUMIFS('Jul 2026'!$J$29:$J$528,'Jul 2026'!$E$29:$E$528,$A22,'Jul 2026'!$I$29:$I$528,"Opening Balance")+SUMIFS('Aug 2026'!$J$29:$J$528,'Aug 2026'!$E$29:$E$528,$A22,'Aug 2026'!$I$29:$I$528,"Opening Balance")+SUMIFS('Sep 2026'!$J$29:$J$528,'Sep 2026'!$E$29:$E$528,$A22,'Sep 2026'!$I$29:$I$528,"Opening Balance")+SUMIFS('Oct 2026'!$J$29:$J$528,'Oct 2026'!$E$29:$E$528,$A22,'Oct 2026'!$I$29:$I$528,"Opening Balance")+SUMIFS('Nov 2026'!$J$29:$J$528,'Nov 2026'!$E$29:$E$528,$A22,'Nov 2026'!$I$29:$I$528,"Opening Balance")+SUMIFS('Dec 2026'!$J$29:$J$528,'Dec 2026'!$E$29:$E$528,$A22,'Dec 2026'!$I$29:$I$528,"Opening Balance") -> 0 | E22: =C22+D22-B22 -> -3300
A23: Utilities | B23: =SUMIFS('Jan 2026'!$J$29:$J$528,'Jan 2026'!$E$29:$E$528,$A23,'Jan 2026'!$I$29:$I$528,"Expense")+SUMIFS('Feb 2026'!$J$29:$J$528,'Feb 2026'!$E$29:$E$528,$A23,'Feb 2026'!$I$29:$I$528,"Expense")+SUMIFS('Mar 2026'!$J$29:$J$528,'Mar 2026'!$E$29:$E$528,$A23,'Mar 2026'!$I$29:$I$528,"Expense")+SUMIFS('Apr 2026'!$J$29:$J$528,'Apr 2026'!$E$29:$E$528,$A23,'Apr 2026'!$I$29:$I$528,"Expense")+SUMIFS('May 2026'!$J$29:$J$528,'May 2026'!$E$29:$E$528,$A23,'May 2026'!$I$29:$I$528,"Expense")+SUMIFS('Jun 2026'!$J$29:$J$528,'Jun 2026'!$E$29:$E$528,$A23,'Jun 2026'!$I$29:$I$528,"Expense")+SUMIFS('Jul 2026'!$J$29:$J$528,'Jul 2026'!$E$29:$E$528,$A23,'Jul 2026'!$I$29:$I$528,"Expense")+SUMIFS('Aug 2026'!$J$29:$J$528,'Aug 2026'!$E$29:$E$528,$A23,'Aug 2026'!$I$29:$I$528,"Expense")+SUMIFS('Sep 2026'!$J$29:$J$528,'Sep 2026'!$E$29:$E$528,$A23,'Sep 2026'!$I$29:$I$528,"Expense")+SUMIFS('Oct 2026'!$J$29:$J$528,'Oct 2026'!$E$29:$E$528,$A23,'Oct 2026'!$I$29:$I$528,"Expense")+SUMIFS('Nov 2026'!$J$29:$J$528,'Nov 2026'!$E$29:$E$528,$A23,'Nov 2026'!$I$29:$I$528,"Expense")+SUMIFS('Dec 2026'!$J$29:$J$528,'Dec 2026'!$E$29:$E$528,$A23,'Dec 2026'!$I$29:$I$528,"Expense") -> 117.91 | C23: =SUMIFS('Jan 2026'!$J$29:$J$528,'Jan 2026'!$E$29:$E$528,$A23,'Jan 2026'!$I$29:$I$528,"Income")+SUMIFS('Feb 2026'!$J$29:$J$528,'Feb 2026'!$E$29:$E$528,$A23,'Feb 2026'!$I$29:$I$528,"Income")+SUMIFS('Mar 2026'!$J$29:$J$528,'Mar 2026'!$E$29:$E$528,$A23,'Mar 2026'!$I$29:$I$528,"Income")+SUMIFS('Apr 2026'!$J$29:$J$528,'Apr 2026'!$E$29:$E$528,$A23,'Apr 2026'!$I$29:$I$528,"Income")+SUMIFS('May 2026'!$J$29:$J$528,'May 2026'!$E$29:$E$528,$A23,'May 2026'!$I$29:$I$528,"Income")+SUMIFS('Jun 2026'!$J$29:$J$528,'Jun 2026'!$E$29:$E$528,$A23,'Jun 2026'!$I$29:$I$528,"Income")+SUMIFS('Jul 2026'!$J$29:$J$528,'Jul 2026'!$E$29:$E$528,$A23,'Jul 2026'!$I$29:$I$528,"Income")+SUMIFS('Aug 2026'!$J$29:$J$528,'Aug 2026'!$E$29:$E$528,$A23,'Aug 2026'!$I$29:$I$528,"Income")+SUMIFS('Sep 2026'!$J$29:$J$528,'Sep 2026'!$E$29:$E$528,$A23,'Sep 2026'!$I$29:$I$528,"Income")+SUMIFS('Oct 2026'!$J$29:$J$528,'Oct 2026'!$E$29:$E$528,$A23,'Oct 2026'!$I$29:$I$528,"Income")+SUMIFS('Nov 2026'!$J$29:$J$528,'Nov 2026'!$E$29:$E$528,$A23,'Nov 2026'!$I$29:$I$528,"Income")+SUMIFS('Dec 2026'!$J$29:$J$528,'Dec 2026'!$E$29:$E$528,$A23,'Dec 2026'!$I$29:$I$528,"Income") -> 0 | D23: =SUMIFS('Jan 2026'!$J$29:$J$528,'Jan 2026'!$E$29:$E$528,$A23,'Jan 2026'!$I$29:$I$528,"Opening Balance")+SUMIFS('Feb 2026'!$J$29:$J$528,'Feb 2026'!$E$29:$E$528,$A23,'Feb 2026'!$I$29:$I$528,"Opening Balance")+SUMIFS('Mar 2026'!$J$29:$J$528,'Mar 2026'!$E$29:$E$528,$A23,'Mar 2026'!$I$29:$I$528,"Opening Balance")+SUMIFS('Apr 2026'!$J$29:$J$528,'Apr 2026'!$E$29:$E$528,$A23,'Apr 2026'!$I$29:$I$528,"Opening Balance")+SUMIFS('May 2026'!$J$29:$J$528,'May 2026'!$E$29:$E$528,$A23,'May 2026'!$I$29:$I$528,"Opening Balance")+SUMIFS('Jun 2026'!$J$29:$J$528,'Jun 2026'!$E$29:$E$528,$A23,'Jun 2026'!$I$29:$I$528,"Opening Balance")+SUMIFS('Jul 2026'!$J$29:$J$528,'Jul 2026'!$E$29:$E$528,$A23,'Jul 2026'!$I$29:$I$528,"Opening Balance")+SUMIFS('Aug 2026'!$J$29:$J$528,'Aug 2026'!$E$29:$E$528,$A23,'Aug 2026'!$I$29:$I$528,"Opening Balance")+SUMIFS('Sep 2026'!$J$29:$J$528,'Sep 2026'!$E$29:$E$528,$A23,'Sep 2026'!$I$29:$I$528,"Opening Balance")+SUMIFS('Oct 2026'!$J$29:$J$528,'Oct 2026'!$E$29:$E$528,$A23,'Oct 2026'!$I$29:$I$528,"Opening Balance")+SUMIFS('Nov 2026'!$J$29:$J$528,'Nov 2026'!$E$29:$E$528,$A23,'Nov 2026'!$I$29:$I$528,"Opening Balance")+SUMIFS('Dec 2026'!$J$29:$J$528,'Dec 2026'!$E$29:$E$528,$A23,'Dec 2026'!$I$29:$I$528,"Opening Balance") -> 0 | E23: =C23+D23-B23 -> -117.91
A24: Groceries | B24: =SUMIFS('Jan 2026'!$J$29:$J$528,'Jan 2026'!$E$29:$E$528,$A24,'Jan 2026'!$I$29:$I$528,"Expense")+SUMIFS('Feb 2026'!$J$29:$J$528,'Feb 2026'!$E$29:$E$528,$A24,'Feb 2026'!$I$29:$I$528,"Expense")+SUMIFS('Mar 2026'!$J$29:$J$528,'Mar 2026'!$E$29:$E$528,$A24,'Mar 2026'!$I$29:$I$528,"Expense")+SUMIFS('Apr 2026'!$J$29:$J$528,'Apr 2026'!$E$29:$E$528,$A24,'Apr 2026'!$I$29:$I$528,"Expense")+SUMIFS('May 2026'!$J$29:$J$528,'May 2026'!$E$29:$E$528,$A24,'May 2026'!$I$29:$I$528,"Expense")+SUMIFS('Jun 2026'!$J$29:$J$528,'Jun 2026'!$E$29:$E$528,$A24,'Jun 2026'!$I$29:$I$528,"Expense")+SUMIFS('Jul 2026'!$J$29:$J$528,'Jul 2026'!$E$29:$E$528,$A24,'Jul 2026'!$I$29:$I$528,"Expense")+SUMIFS('Aug 2026'!$J$29:$J$528,'Aug 2026'!$E$29:$E$528,$A24,'Aug 2026'!$I$29:$I$528,"Expense")+SUMIFS('Sep 2026'!$J$29:$J$528,'Sep 2026'!$E$29:$E$528,$A24,'Sep 2026'!$I$29:$I$528,"Expense")+SUMIFS('Oct 2026'!$J$29:$J$528,'Oct 2026'!$E$29:$E$528,$A24,'Oct 2026'!$I$29:$I$528,"Expense")+SUMIFS('Nov 2026'!$J$29:$J$528,'Nov 2026'!$E$29:$E$528,$A24,'Nov 2026'!$I$29:$I$528,"Expense")+SUMIFS('Dec 2026'!$J$29:$J$528,'Dec 2026'!$E$29:$E$528,$A24,'Dec 2026'!$I$29:$I$528,"Expense") -> 757.58 | C24: =SUMIFS('Jan 2026'!$J$29:$J$528,'Jan 2026'!$E$29:$E$528,$A24,'Jan 2026'!$I$29:$I$528,"Income")+SUMIFS('Feb 2026'!$J$29:$J$528,'Feb 2026'!$E$29:$E$528,$A24,'Feb 2026'!$I$29:$I$528,"Income")+SUMIFS('Mar 2026'!$J$29:$J$528,'Mar 2026'!$E$29:$E$528,$A24,'Mar 2026'!$I$29:$I$528,"Income")+SUMIFS('Apr 2026'!$J$29:$J$528,'Apr 2026'!$E$29:$E$528,$A24,'Apr 2026'!$I$29:$I$528,"Income")+SUMIFS('May 2026'!$J$29:$J$528,'May 2026'!$E$29:$E$528,$A24,'May 2026'!$I$29:$I$528,"Income")+SUMIFS('Jun 2026'!$J$29:$J$528,'Jun 2026'!$E$29:$E$528,$A24,'Jun 2026'!$I$29:$I$528,"Income")+SUMIFS('Jul 2026'!$J$29:$J$528,'Jul 2026'!$E$29:$E$528,$A24,'Jul 2026'!$I$29:$I$528,"Income")+SUMIFS('Aug 2026'!$J$29:$J$528,'Aug 2026'!$E$29:$E$528,$A24,'Aug 2026'!$I$29:$I$528,"Income")+SUMIFS('Sep 2026'!$J$29:$J$528,'Sep 2026'!$E$29:$E$528,$A24,'Sep 2026'!$I$29:$I$528,"Income")+SUMIFS('Oct 2026'!$J$29:$J$528,'Oct 2026'!$E$29:$E$528,$A24,'Oct 2026'!$I$29:$I$528,"Income")+SUMIFS('Nov 2026'!$J$29:$J$528,'Nov 2026'!$E$29:$E$528,$A24,'Nov 2026'!$I$29:$I$528,"Income")+SUMIFS('Dec 2026'!$J$29:$J$528,'Dec 2026'!$E$29:$E$528,$A24,'Dec 2026'!$I$29:$I$528,"Income") -> 0 | D24: =SUMIFS('Jan 2026'!$J$29:$J$528,'Jan 2026'!$E$29:$E$528,$A24,'Jan 2026'!$I$29:$I$528,"Opening Balance")+SUMIFS('Feb 2026'!$J$29:$J$528,'Feb 2026'!$E$29:$E$528,$A24,'Feb 2026'!$I$29:$I$528,"Opening Balance")+SUMIFS('Mar 2026'!$J$29:$J$528,'Mar 2026'!$E$29:$E$528,$A24,'Mar 2026'!$I$29:$I$528,"Opening Balance")+SUMIFS('Apr 2026'!$J$29:$J$528,'Apr 2026'!$E$29:$E$528,$A24,'Apr 2026'!$I$29:$I$528,"Opening Balance")+SUMIFS('May 2026'!$J$29:$J$528,'May 2026'!$E$29:$E$528,$A24,'May 2026'!$I$29:$I$528,"Opening Balance")+SUMIFS('Jun 2026'!$J$29:$J$528,'Jun 2026'!$E$29:$E$528,$A24,'Jun 2026'!$I$29:$I$528,"Opening Balance")+SUMIFS('Jul 2026'!$J$29:$J$528,'Jul 2026'!$E$29:$E$528,$A24,'Jul 2026'!$I$29:$I$528,"Opening Balance")+SUMIFS('Aug 2026'!$J$29:$J$528,'Aug 2026'!$E$29:$E$528,$A24,'Aug 2026'!$I$29:$I$528,"Opening Balance")+SUMIFS('Sep 2026'!$J$29:$J$528,'Sep 2026'!$E$29:$E$528,$A24,'Sep 2026'!$I$29:$I$528,"Opening Balance")+SUMIFS('Oct 2026'!$J$29:$J$528,'Oct 2026'!$E$29:$E$528,$A24,'Oct 2026'!$I$29:$I$528,"Opening Balance")+SUMIFS('Nov 2026'!$J$29:$J$528,'Nov 2026'!$E$29:$E$528,$A24,'Nov 2026'!$I$29:$I$528,"Opening Balance")+SUMIFS('Dec 2026'!$J$29:$J$528,'Dec 2026'!$E$29:$E$528,$A24,'Dec 2026'!$I$29:$I$528,"Opening Balance") -> 0 | E24: =C24+D24-B24 -> -757.58
A25: Dining | B25: =SUMIFS('Jan 2026'!$J$29:$J$528,'Jan 2026'!$E$29:$E$528,$A25,'Jan 2026'!$I$29:$I$528,"Expense")+SUMIFS('Feb 2026'!$J$29:$J$528,'Feb 2026'!$E$29:$E$528,$A25,'Feb 2026'!$I$29:$I$528,"Expense")+SUMIFS('Mar 2026'!$J$29:$J$528,'Mar 2026'!$E$29:$E$528,$A25,'Mar 2026'!$I$29:$I$528,"Expense")+SUMIFS('Apr 2026'!$J$29:$J$528,'Apr 2026'!$E$29:$E$528,$A25,'Apr 2026'!$I$29:$I$528,"Expense")+SUMIFS('May 2026'!$J$29:$J$528,'May 2026'!$E$29:$E$528,$A25,'May 2026'!$I$29:$I$528,"Expense")+SUMIFS('Jun 2026'!$J$29:$J$528,'Jun 2026'!$E$29:$E$528,$A25,'Jun 2026'!$I$29:$I$528,"Expense")+SUMIFS('Jul 2026'!$J$29:$J$528,'Jul 2026'!$E$29:$E$528,$A25,'Jul 2026'!$I$29:$I$528,"Expense")+SUMIFS('Aug 2026'!$J$29:$J$528,'Aug 2026'!$E$29:$E$528,$A25,'Aug 2026'!$I$29:$I$528,"Expense")+SUMIFS('Sep 2026'!$J$29:$J$528,'Sep 2026'!$E$29:$E$528,$A25,'Sep 2026'!$I$29:$I$528,"Expense")+SUMIFS('Oct 2026'!$J$29:$J$528,'Oct 2026'!$E$29:$E$528,$A25,'Oct 2026'!$I$29:$I$528,"Expense")+SUMIFS('Nov 2026'!$J$29:$J$528,'Nov 2026'!$E$29:$E$528,$A25,'Nov 2026'!$I$29:$I$528,"Expense")+SUMIFS('Dec 2026'!$J$29:$J$528,'Dec 2026'!$E$29:$E$528,$A25,'Dec 2026'!$I$29:$I$528,"Expense") -> 1053.29 | C25: =SUMIFS('Jan 2026'!$J$29:$J$528,'Jan 2026'!$E$29:$E$528,$A25,'Jan 2026'!$I$29:$I$528,"Income")+SUMIFS('Feb 2026'!$J$29:$J$528,'Feb 2026'!$E$29:$E$528,$A25,'Feb 2026'!$I$29:$I$528,"Income")+SUMIFS('Mar 2026'!$J$29:$J$528,'Mar 2026'!$E$29:$E$528,$A25,'Mar 2026'!$I$29:$I$528,"Income")+SUMIFS('Apr 2026'!$J$29:$J$528,'Apr 2026'!$E$29:$E$528,$A25,'Apr 2026'!$I$29:$I$528,"Income")+SUMIFS('May 2026'!$J$29:$J$528,'May 2026'!$E$29:$E$528,$A25,'May 2026'!$I$29:$I$528,"Income")+SUMIFS('Jun 2026'!$J$29:$J$528,'Jun 2026'!$E$29:$E$528,$A25,'Jun 2026'!$I$29:$I$528,"Income")+SUMIFS('Jul 2026'!$J$29:$J$528,'Jul 2026'!$E$29:$E$528,$A25,'Jul 2026'!$I$29:$I$528,"Income")+SUMIFS('Aug 2026'!$J$29:$J$528,'Aug 2026'!$E$29:$E$528,$A25,'Aug 2026'!$I$29:$I$528,"Income")+SUMIFS('Sep 2026'!$J$29:$J$528,'Sep 2026'!$E$29:$E$528,$A25,'Sep 2026'!$I$29:$I$528,"Income")+SUMIFS('Oct 2026'!$J$29:$J$528,'Oct 2026'!$E$29:$E$528,$A25,'Oct 2026'!$I$29:$I$528,"Income")+SUMIFS('Nov 2026'!$J$29:$J$528,'Nov 2026'!$E$29:$E$528,$A25,'Nov 2026'!$I$29:$I$528,"Income")+SUMIFS('Dec 2026'!$J$29:$J$528,'Dec 2026'!$E$29:$E$528,$A25,'Dec 2026'!$I$29:$I$528,"Income") -> 0 | D25: =SUMIFS('Jan 2026'!$J$29:$J$528,'Jan 2026'!$E$29:$E$528,$A25,'Jan 2026'!$I$29:$I$528,"Opening Balance")+SUMIFS('Feb 2026'!$J$29:$J$528,'Feb 2026'!$E$29:$E$528,$A25,'Feb 2026'!$I$29:$I$528,"Opening Balance")+SUMIFS('Mar 2026'!$J$29:$J$528,'Mar 2026'!$E$29:$E$528,$A25,'Mar 2026'!$I$29:$I$528,"Opening Balance")+SUMIFS('Apr 2026'!$J$29:$J$528,'Apr 2026'!$E$29:$E$528,$A25,'Apr 2026'!$I$29:$I$528,"Opening Balance")+SUMIFS('May 2026'!$J$29:$J$528,'May 2026'!$E$29:$E$528,$A25,'May 2026'!$I$29:$I$528,"Opening Balance")+SUMIFS('Jun 2026'!$J$29:$J$528,'Jun 2026'!$E$29:$E$528,$A25,'Jun 2026'!$I$29:$I$528,"Opening Balance")+SUMIFS('Jul 2026'!$J$29:$J$528,'Jul 2026'!$E$29:$E$528,$A25,'Jul 2026'!$I$29:$I$528,"Opening Balance")+SUMIFS('Aug 2026'!$J$29:$J$528,'Aug 2026'!$E$29:$E$528,$A25,'Aug 2026'!$I$29:$I$528,"Opening Balance")+SUMIFS('Sep 2026'!$J$29:$J$528,'Sep 2026'!$E$29:$E$528,$A25,'Sep 2026'!$I$29:$I$528,"Opening Balance")+SUMIFS('Oct 2026'!$J$29:$J$528,'Oct 2026'!$E$29:$E$528,$A25,'Oct 2026'!$I$29:$I$528,"Opening Balance")+SUMIFS('Nov 2026'!$J$29:$J$528,'Nov 2026'!$E$29:$E$528,$A25,'Nov 2026'!$I$29:$I$528,"Opening Balance")+SUMIFS('Dec 2026'!$J$29:$J$528,'Dec 2026'!$E$29:$E$528,$A25,'Dec 2026'!$I$29:$I$528,"Opening Balance") -> 0 | E25: =C25+D25-B25 -> -1053.29
A26: Transportation | B26: =SUMIFS('Jan 2026'!$J$29:$J$528,'Jan 2026'!$E$29:$E$528,$A26,'Jan 2026'!$I$29:$I$528,"Expense")+SUMIFS('Feb 2026'!$J$29:$J$528,'Feb 2026'!$E$29:$E$528,$A26,'Feb 2026'!$I$29:$I$528,"Expense")+SUMIFS('Mar 2026'!$J$29:$J$528,'Mar 2026'!$E$29:$E$528,$A26,'Mar 2026'!$I$29:$I$528,"Expense")+SUMIFS('Apr 2026'!$J$29:$J$528,'Apr 2026'!$E$29:$E$528,$A26,'Apr 2026'!$I$29:$I$528,"Expense")+SUMIFS('May 2026'!$J$29:$J$528,'May 2026'!$E$29:$E$528,$A26,'May 2026'!$I$29:$I$528,"Expense")+SUMIFS('Jun 2026'!$J$29:$J$528,'Jun 2026'!$E$29:$E$528,$A26,'Jun 2026'!$I$29:$I$528,"Expense")+SUMIFS('Jul 2026'!$J$29:$J$528,'Jul 2026'!$E$29:$E$528,$A26,'Jul 2026'!$I$29:$I$528,"Expense")+SUMIFS('Aug 2026'!$J$29:$J$528,'Aug 2026'!$E$29:$E$528,$A26,'Aug 2026'!$I$29:$I$528,"Expense")+SUMIFS('Sep 2026'!$J$29:$J$528,'Sep 2026'!$E$29:$E$528,$A26,'Sep 2026'!$I$29:$I$528,"Expense")+SUMIFS('Oct 2026'!$J$29:$J$528,'Oct 2026'!$E$29:$E$528,$A26,'Oct 2026'!$I$29:$I$528,"Expense")+SUMIFS('Nov 2026'!$J$29:$J$528,'Nov 2026'!$E$29:$E$528,$A26,'Nov 2026'!$I$29:$I$528,"Expense")+SUMIFS('Dec 2026'!$J$29:$J$528,'Dec 2026'!$E$29:$E$528,$A26,'Dec 2026'!$I$29:$I$528,"Expense") -> 298.1 | C26: =SUMIFS('Jan 2026'!$J$29:$J$528,'Jan 2026'!$E$29:$E$528,$A26,'Jan 2026'!$I$29:$I$528,"Income")+SUMIFS('Feb 2026'!$J$29:$J$528,'Feb 2026'!$E$29:$E$528,$A26,'Feb 2026'!$I$29:$I$528,"Income")+SUMIFS('Mar 2026'!$J$29:$J$528,'Mar 2026'!$E$29:$E$528,$A26,'Mar 2026'!$I$29:$I$528,"Income")+SUMIFS('Apr 2026'!$J$29:$J$528,'Apr 2026'!$E$29:$E$528,$A26,'Apr 2026'!$I$29:$I$528,"Income")+SUMIFS('May 2026'!$J$29:$J$528,'May 2026'!$E$29:$E$528,$A26,'May 2026'!$I$29:$I$528,"Income")+SUMIFS('Jun 2026'!$J$29:$J$528,'Jun 2026'!$E$29:$E$528,$A26,'Jun 2026'!$I$29:$I$528,"Income")+SUMIFS('Jul 2026'!$J$29:$J$528,'Jul 2026'!$E$29:$E$528,$A26,'Jul 2026'!$I$29:$I$528,"Income")+SUMIFS('Aug 2026'!$J$29:$J$528,'Aug 2026'!$E$29:$E$528,$A26,'Aug 2026'!$I$29:$I$528,"Income")+SUMIFS('Sep 2026'!$J$29:$J$528,'Sep 2026'!$E$29:$E$528,$A26,'Sep 2026'!$I$29:$I$528,"Income")+SUMIFS('Oct 2026'!$J$29:$J$528,'Oct 2026'!$E$29:$E$528,$A26,'Oct 2026'!$I$29:$I$528,"Income")+SUMIFS('Nov 2026'!$J$29:$J$528,'Nov 2026'!$E$29:$E$528,$A26,'Nov 2026'!$I$29:$I$528,"Income")+SUMIFS('Dec 2026'!$J$29:$J$528,'Dec 2026'!$E$29:$E$528,$A26,'Dec 2026'!$I$29:$I$528,"Income") -> 0 | D26: =SUMIFS('Jan 2026'!$J$29:$J$528,'Jan 2026'!$E$29:$E$528,$A26,'Jan 2026'!$I$29:$I$528,"Opening Balance")+SUMIFS('Feb 2026'!$J$29:$J$528,'Feb 2026'!$E$29:$E$528,$A26,'Feb 2026'!$I$29:$I$528,"Opening Balance")+SUMIFS('Mar 2026'!$J$29:$J$528,'Mar 2026'!$E$29:$E$528,$A26,'Mar 2026'!$I$29:$I$528,"Opening Balance")+SUMIFS('Apr 2026'!$J$29:$J$528,'Apr 2026'!$E$29:$E$528,$A26,'Apr 2026'!$I$29:$I$528,"Opening Balance")+SUMIFS('May 2026'!$J$29:$J$528,'May 2026'!$E$29:$E$528,$A26,'May 2026'!$I$29:$I$528,"Opening Balance")+SUMIFS('Jun 2026'!$J$29:$J$528,'Jun 2026'!$E$29:$E$528,$A26,'Jun 2026'!$I$29:$I$528,"Opening Balance")+SUMIFS('Jul 2026'!$J$29:$J$528,'Jul 2026'!$E$29:$E$528,$A26,'Jul 2026'!$I$29:$I$528,"Opening Balance")+SUMIFS('Aug 2026'!$J$29:$J$528,'Aug 2026'!$E$29:$E$528,$A26,'Aug 2026'!$I$29:$I$528,"Opening Balance")+SUMIFS('Sep 2026'!$J$29:$J$528,'Sep 2026'!$E$29:$E$528,$A26,'Sep 2026'!$I$29:$I$528,"Opening Balance")+SUMIFS('Oct 2026'!$J$29:$J$528,'Oct 2026'!$E$29:$E$528,$A26,'Oct 2026'!$I$29:$I$528,"Opening Balance")+SUMIFS('Nov 2026'!$J$29:$J$528,'Nov 2026'!$E$29:$E$528,$A26,'Nov 2026'!$I$29:$I$528,"Opening Balance")+SUMIFS('Dec 2026'!$J$29:$J$528,'Dec 2026'!$E$29:$E$528,$A26,'Dec 2026'!$I$29:$I$528,"Opening Balance") -> 0 | E26: =C26+D26-B26 -> -298.1
A27: Health & Medical | B27: =SUMIFS('Jan 2026'!$J$29:$J$528,'Jan 2026'!$E$29:$E$528,$A27,'Jan 2026'!$I$29:$I$528,"Expense")+SUMIFS('Feb 2026'!$J$29:$J$528,'Feb 2026'!$E$29:$E$528,$A27,'Feb 2026'!$I$29:$I$528,"Expense")+SUMIFS('Mar 2026'!$J$29:$J$528,'Mar 2026'!$E$29:$E$528,$A27,'Mar 2026'!$I$29:$I$528,"Expense")+SUMIFS('Apr 2026'!$J$29:$J$528,'Apr 2026'!$E$29:$E$528,$A27,'Apr 2026'!$I$29:$I$528,"Expense")+SUMIFS('May 2026'!$J$29:$J$528,'May 2026'!$E$29:$E$528,$A27,'May 2026'!$I$29:$I$528,"Expense")+SUMIFS('Jun 2026'!$J$29:$J$528,'Jun 2026'!$E$29:$E$528,$A27,'Jun 2026'!$I$29:$I$528,"Expense")+SUMIFS('Jul 2026'!$J$29:$J$528,'Jul 2026'!$E$29:$E$528,$A27,'Jul 2026'!$I$29:$I$528,"Expense")+SUMIFS('Aug 2026'!$J$29:$J$528,'Aug 2026'!$E$29:$E$528,$A27,'Aug 2026'!$I$29:$I$528,"Expense")+SUMIFS('Sep 2026'!$J$29:$J$528,'Sep 2026'!$E$29:$E$528,$A27,'Sep 2026'!$I$29:$I$528,"Expense")+SUMIFS('Oct 2026'!$J$29:$J$528,'Oct 2026'!$E$29:$E$528,$A27,'Oct 2026'!$I$29:$I$528,"Expense")+SUMIFS('Nov 2026'!$J$29:$J$528,'Nov 2026'!$E$29:$E$528,$A27,'Nov 2026'!$I$29:$I$528,"Expense")+SUMIFS('Dec 2026'!$J$29:$J$528,'Dec 2026'!$E$29:$E$528,$A27,'Dec 2026'!$I$29:$I$528,"Expense") -> 0 | C27: =SUMIFS('Jan 2026'!$J$29:$J$528,'Jan 2026'!$E$29:$E$528,$A27,'Jan 2026'!$I$29:$I$528,"Income")+SUMIFS('Feb 2026'!$J$29:$J$528,'Feb 2026'!$E$29:$E$528,$A27,'Feb 2026'!$I$29:$I$528,"Income")+SUMIFS('Mar 2026'!$J$29:$J$528,'Mar 2026'!$E$29:$E$528,$A27,'Mar 2026'!$I$29:$I$528,"Income")+SUMIFS('Apr 2026'!$J$29:$J$528,'Apr 2026'!$E$29:$E$528,$A27,'Apr 2026'!$I$29:$I$528,"Income")+SUMIFS('May 2026'!$J$29:$J$528,'May 2026'!$E$29:$E$528,$A27,'May 2026'!$I$29:$I$528,"Income")+SUMIFS('Jun 2026'!$J$29:$J$528,'Jun 2026'!$E$29:$E$528,$A27,'Jun 2026'!$I$29:$I$528,"Income")+SUMIFS('Jul 2026'!$J$29:$J$528,'Jul 2026'!$E$29:$E$528,$A27,'Jul 2026'!$I$29:$I$528,"Income")+SUMIFS('Aug 2026'!$J$29:$J$528,'Aug 2026'!$E$29:$E$528,$A27,'Aug 2026'!$I$29:$I$528,"Income")+SUMIFS('Sep 2026'!$J$29:$J$528,'Sep 2026'!$E$29:$E$528,$A27,'Sep 2026'!$I$29:$I$528,"Income")+SUMIFS('Oct 2026'!$J$29:$J$528,'Oct 2026'!$E$29:$E$528,$A27,'Oct 2026'!$I$29:$I$528,"Income")+SUMIFS('Nov 2026'!$J$29:$J$528,'Nov 2026'!$E$29:$E$528,$A27,'Nov 2026'!$I$29:$I$528,"Income")+SUMIFS('Dec 2026'!$J$29:$J$528,'Dec 2026'!$E$29:$E$528,$A27,'Dec 2026'!$I$29:$I$528,"Income") -> 0 | D27: =SUMIFS('Jan 2026'!$J$29:$J$528,'Jan 2026'!$E$29:$E$528,$A27,'Jan 2026'!$I$29:$I$528,"Opening Balance")+SUMIFS('Feb 2026'!$J$29:$J$528,'Feb 2026'!$E$29:$E$528,$A27,'Feb 2026'!$I$29:$I$528,"Opening Balance")+SUMIFS('Mar 2026'!$J$29:$J$528,'Mar 2026'!$E$29:$E$528,$A27,'Mar 2026'!$I$29:$I$528,"Opening Balance")+SUMIFS('Apr 2026'!$J$29:$J$528,'Apr 2026'!$E$29:$E$528,$A27,'Apr 2026'!$I$29:$I$528,"Opening Balance")+SUMIFS('May 2026'!$J$29:$J$528,'May 2026'!$E$29:$E$528,$A27,'May 2026'!$I$29:$I$528,"Opening Balance")+SUMIFS('Jun 2026'!$J$29:$J$528,'Jun 2026'!$E$29:$E$528,$A27,'Jun 2026'!$I$29:$I$528,"Opening Balance")+SUMIFS('Jul 2026'!$J$29:$J$528,'Jul 2026'!$E$29:$E$528,$A27,'Jul 2026'!$I$29:$I$528,"Opening Balance")+SUMIFS('Aug 2026'!$J$29:$J$528,'Aug 2026'!$E$29:$E$528,$A27,'Aug 2026'!$I$29:$I$528,"Opening Balance")+SUMIFS('Sep 2026'!$J$29:$J$528,'Sep 2026'!$E$29:$E$528,$A27,'Sep 2026'!$I$29:$I$528,"Opening Balance")+SUMIFS('Oct 2026'!$J$29:$J$528,'Oct 2026'!$E$29:$E$528,$A27,'Oct 2026'!$I$29:$I$528,"Opening Balance")+SUMIFS('Nov 2026'!$J$29:$J$528,'Nov 2026'!$E$29:$E$528,$A27,'Nov 2026'!$I$29:$I$528,"Opening Balance")+SUMIFS('Dec 2026'!$J$29:$J$528,'Dec 2026'!$E$29:$E$528,$A27,'Dec 2026'!$I$29:$I$528,"Opening Balance") -> 0 | E27: =C27+D27-B27 -> 0
A28: Insurance | B28: =SUMIFS('Jan 2026'!$J$29:$J$528,'Jan 2026'!$E$29:$E$528,$A28,'Jan 2026'!$I$29:$I$528,"Expense")+SUMIFS('Feb 2026'!$J$29:$J$528,'Feb 2026'!$E$29:$E$528,$A28,'Feb 2026'!$I$29:$I$528,"Expense")+SUMIFS('Mar 2026'!$J$29:$J$528,'Mar 2026'!$E$29:$E$528,$A28,'Mar 2026'!$I$29:$I$528,"Expense")+SUMIFS('Apr 2026'!$J$29:$J$528,'Apr 2026'!$E$29:$E$528,$A28,'Apr 2026'!$I$29:$I$528,"Expense")+SUMIFS('May 2026'!$J$29:$J$528,'May 2026'!$E$29:$E$528,$A28,'May 2026'!$I$29:$I$528,"Expense")+SUMIFS('Jun 2026'!$J$29:$J$528,'Jun 2026'!$E$29:$E$528,$A28,'Jun 2026'!$I$29:$I$528,"Expense")+SUMIFS('Jul 2026'!$J$29:$J$528,'Jul 2026'!$E$29:$E$528,$A28,'Jul 2026'!$I$29:$I$528,"Expense")+SUMIFS('Aug 2026'!$J$29:$J$528,'Aug 2026'!$E$29:$E$528,$A28,'Aug 2026'!$I$29:$I$528,"Expense")+SUMIFS('Sep 2026'!$J$29:$J$528,'Sep 2026'!$E$29:$E$528,$A28,'Sep 2026'!$I$29:$I$528,"Expense")+SUMIFS('Oct 2026'!$J$29:$J$528,'Oct 2026'!$E$29:$E$528,$A28,'Oct 2026'!$I$29:$I$528,"Expense")+SUMIFS('Nov 2026'!$J$29:$J$528,'Nov 2026'!$E$29:$E$528,$A28,'Nov 2026'!$I$29:$I$528,"Expense")+SUMIFS('Dec 2026'!$J$29:$J$528,'Dec 2026'!$E$29:$E$528,$A28,'Dec 2026'!$I$29:$I$528,"Expense") -> 0 | C28: =SUMIFS('Jan 2026'!$J$29:$J$528,'Jan 2026'!$E$29:$E$528,$A28,'Jan 2026'!$I$29:$I$528,"Income")+SUMIFS('Feb 2026'!$J$29:$J$528,'Feb 2026'!$E$29:$E$528,$A28,'Feb 2026'!$I$29:$I$528,"Income")+SUMIFS('Mar 2026'!$J$29:$J$528,'Mar 2026'!$E$29:$E$528,$A28,'Mar 2026'!$I$29:$I$528,"Income")+SUMIFS('Apr 2026'!$J$29:$J$528,'Apr 2026'!$E$29:$E$528,$A28,'Apr 2026'!$I$29:$I$528,"Income")+SUMIFS('May 2026'!$J$29:$J$528,'May 2026'!$E$29:$E$528,$A28,'May 2026'!$I$29:$I$528,"Income")+SUMIFS('Jun 2026'!$J$29:$J$528,'Jun 2026'!$E$29:$E$528,$A28,'Jun 2026'!$I$29:$I$528,"Income")+SUMIFS('Jul 2026'!$J$29:$J$528,'Jul 2026'!$E$29:$E$528,$A28,'Jul 2026'!$I$29:$I$528,"Income")+SUMIFS('Aug 2026'!$J$29:$J$528,'Aug 2026'!$E$29:$E$528,$A28,'Aug 2026'!$I$29:$I$528,"Income")+SUMIFS('Sep 2026'!$J$29:$J$528,'Sep 2026'!$E$29:$E$528,$A28,'Sep 2026'!$I$29:$I$528,"Income")+SUMIFS('Oct 2026'!$J$29:$J$528,'Oct 2026'!$E$29:$E$528,$A28,'Oct 2026'!$I$29:$I$528,"Income")+SUMIFS('Nov 2026'!$J$29:$J$528,'Nov 2026'!$E$29:$E$528,$A28,'Nov 2026'!$I$29:$I$528,"Income")+SUMIFS('Dec 2026'!$J$29:$J$528,'Dec 2026'!$E$29:$E$528,$A28,'Dec 2026'!$I$29:$I$528,"Income") -> 0 | D28: =SUMIFS('Jan 2026'!$J$29:$J$528,'Jan 2026'!$E$29:$E$528,$A28,'Jan 2026'!$I$29:$I$528,"Opening Balance")+SUMIFS('Feb 2026'!$J$29:$J$528,'Feb 2026'!$E$29:$E$528,$A28,'Feb 2026'!$I$29:$I$528,"Opening Balance")+SUMIFS('Mar 2026'!$J$29:$J$528,'Mar 2026'!$E$29:$E$528,$A28,'Mar 2026'!$I$29:$I$528,"Opening Balance")+SUMIFS('Apr 2026'!$J$29:$J$528,'Apr 2026'!$E$29:$E$528,$A28,'Apr 2026'!$I$29:$I$528,"Opening Balance")+SUMIFS('May 2026'!$J$29:$J$528,'May 2026'!$E$29:$E$528,$A28,'May 2026'!$I$29:$I$528,"Opening Balance")+SUMIFS('Jun 2026'!$J$29:$J$528,'Jun 2026'!$E$29:$E$528,$A28,'Jun 2026'!$I$29:$I$528,"Opening Balance")+SUMIFS('Jul 2026'!$J$29:$J$528,'Jul 2026'!$E$29:$E$528,$A28,'Jul 2026'!$I$29:$I$528,"Opening Balance")+SUMIFS('Aug 2026'!$J$29:$J$528,'Aug 2026'!$E$29:$E$528,$A28,'Aug 2026'!$I$29:$I$528,"Opening Balance")+SUMIFS('Sep 2026'!$J$29:$J$528,'Sep 2026'!$E$29:$E$528,$A28,'Sep 2026'!$I$29:$I$528,"Opening Balance")+SUMIFS('Oct 2026'!$J$29:$J$528,'Oct 2026'!$E$29:$E$528,$A28,'Oct 2026'!$I$29:$I$528,"Opening Balance")+SUMIFS('Nov 2026'!$J$29:$J$528,'Nov 2026'!$E$29:$E$528,$A28,'Nov 2026'!$I$29:$I$528,"Opening Balance")+SUMIFS('Dec 2026'!$J$29:$J$528,'Dec 2026'!$E$29:$E$528,$A28,'Dec 2026'!$I$29:$I$528,"Opening Balance") -> 0 | E28: =C28+D28-B28 -> 0
A29: Debt Payments | B29: =SUMIFS('Jan 2026'!$J$29:$J$528,'Jan 2026'!$E$29:$E$528,$A29,'Jan 2026'!$I$29:$I$528,"Expense")+SUMIFS('Feb 2026'!$J$29:$J$528,'Feb 2026'!$E$29:$E$528,$A29,'Feb 2026'!$I$29:$I$528,"Expense")+SUMIFS('Mar 2026'!$J$29:$J$528,'Mar 2026'!$E$29:$E$528,$A29,'Mar 2026'!$I$29:$I$528,"Expense")+SUMIFS('Apr 2026'!$J$29:$J$528,'Apr 2026'!$E$29:$E$528,$A29,'Apr 2026'!$I$29:$I$528,"Expense")+SUMIFS('May 2026'!$J$29:$J$528,'May 2026'!$E$29:$E$528,$A29,'May 2026'!$I$29:$I$528,"Expense")+SUMIFS('Jun 2026'!$J$29:$J$528,'Jun 2026'!$E$29:$E$528,$A29,'Jun 2026'!$I$29:$I$528,"Expense")+SUMIFS('Jul 2026'!$J$29:$J$528,'Jul 2026'!$E$29:$E$528,$A29,'Jul 2026'!$I$29:$I$528,"Expense")+SUMIFS('Aug 2026'!$J$29:$J$528,'Aug 2026'!$E$29:$E$528,$A29,'Aug 2026'!$I$29:$I$528,"Expense")+SUMIFS('Sep 2026'!$J$29:$J$528,'Sep 2026'!$E$29:$E$528,$A29,'Sep 2026'!$I$29:$I$528,"Expense")+SUMIFS('Oct 2026'!$J$29:$J$528,'Oct 2026'!$E$29:$E$528,$A29,'Oct 2026'!$I$29:$I$528,"Expense")+SUMIFS('Nov 2026'!$J$29:$J$528,'Nov 2026'!$E$29:$E$528,$A29,'Nov 2026'!$I$29:$I$528,"Expense")+SUMIFS('Dec 2026'!$J$29:$J$528,'Dec 2026'!$E$29:$E$528,$A29,'Dec 2026'!$I$29:$I$528,"Expense") -> 0 | C29: =SUMIFS('Jan 2026'!$J$29:$J$528,'Jan 2026'!$E$29:$E$528,$A29,'Jan 2026'!$I$29:$I$528,"Income")+SUMIFS('Feb 2026'!$J$29:$J$528,'Feb 2026'!$E$29:$E$528,$A29,'Feb 2026'!$I$29:$I$528,"Income")+SUMIFS('Mar 2026'!$J$29:$J$528,'Mar 2026'!$E$29:$E$528,$A29,'Mar 2026'!$I$29:$I$528,"Income")+SUMIFS('Apr 2026'!$J$29:$J$528,'Apr 2026'!$E$29:$E$528,$A29,'Apr 2026'!$I$29:$I$528,"Income")+SUMIFS('May 2026'!$J$29:$J$528,'May 2026'!$E$29:$E$528,$A29,'May 2026'!$I$29:$I$528,"Income")+SUMIFS('Jun 2026'!$J$29:$J$528,'Jun 2026'!$E$29:$E$528,$A29,'Jun 2026'!$I$29:$I$528,"Income")+SUMIFS('Jul 2026'!$J$29:$J$528,'Jul 2026'!$E$29:$E$528,$A29,'Jul 2026'!$I$29:$I$528,"Income")+SUMIFS('Aug 2026'!$J$29:$J$528,'Aug 2026'!$E$29:$E$528,$A29,'Aug 2026'!$I$29:$I$528,"Income")+SUMIFS('Sep 2026'!$J$29:$J$528,'Sep 2026'!$E$29:$E$528,$A29,'Sep 2026'!$I$29:$I$528,"Income")+SUMIFS('Oct 2026'!$J$29:$J$528,'Oct 2026'!$E$29:$E$528,$A29,'Oct 2026'!$I$29:$I$528,"Income")+SUMIFS('Nov 2026'!$J$29:$J$528,'Nov 2026'!$E$29:$E$528,$A29,'Nov 2026'!$I$29:$I$528,"Income")+SUMIFS('Dec 2026'!$J$29:$J$528,'Dec 2026'!$E$29:$E$528,$A29,'Dec 2026'!$I$29:$I$528,"Income") -> 0 | D29: =SUMIFS('Jan 2026'!$J$29:$J$528,'Jan 2026'!$E$29:$E$528,$A29,'Jan 2026'!$I$29:$I$528,"Opening Balance")+SUMIFS('Feb 2026'!$J$29:$J$528,'Feb 2026'!$E$29:$E$528,$A29,'Feb 2026'!$I$29:$I$528,"Opening Balance")+SUMIFS('Mar 2026'!$J$29:$J$528,'Mar 2026'!$E$29:$E$528,$A29,'Mar 2026'!$I$29:$I$528,"Opening Balance")+SUMIFS('Apr 2026'!$J$29:$J$528,'Apr 2026'!$E$29:$E$528,$A29,'Apr 2026'!$I$29:$I$528,"Opening Balance")+SUMIFS('May 2026'!$J$29:$J$528,'May 2026'!$E$29:$E$528,$A29,'May 2026'!$I$29:$I$528,"Opening Balance")+SUMIFS('Jun 2026'!$J$29:$J$528,'Jun 2026'!$E$29:$E$528,$A29,'Jun 2026'!$I$29:$I$528,"Opening Balance")+SUMIFS('Jul 2026'!$J$29:$J$528,'Jul 2026'!$E$29:$E$528,$A29,'Jul 2026'!$I$29:$I$528,"Opening Balance")+SUMIFS('Aug 2026'!$J$29:$J$528,'Aug 2026'!$E$29:$E$528,$A29,'Aug 2026'!$I$29:$I$528,"Opening Balance")+SUMIFS('Sep 2026'!$J$29:$J$528,'Sep 2026'!$E$29:$E$528,$A29,'Sep 2026'!$I$29:$I$528,"Opening Balance")+SUMIFS('Oct 2026'!$J$29:$J$528,'Oct 2026'!$E$29:$E$528,$A29,'Oct 2026'!$I$29:$I$528,"Opening Balance")+SUMIFS('Nov 2026'!$J$29:$J$528,'Nov 2026'!$E$29:$E$528,$A29,'Nov 2026'!$I$29:$I$528,"Opening Balance")+SUMIFS('Dec 2026'!$J$29:$J$528,'Dec 2026'!$E$29:$E$528,$A29,'Dec 2026'!$I$29:$I$528,"Opening Balance") -> 0 | E29: =C29+D29-B29 -> 0
A30: Savings & Investments | B30: =SUMIFS('Jan 2026'!$J$29:$J$528,'Jan 2026'!$E$29:$E$528,$A30,'Jan 2026'!$I$29:$I$528,"Expense")+SUMIFS('Feb 2026'!$J$29:$J$528,'Feb 2026'!$E$29:$E$528,$A30,'Feb 2026'!$I$29:$I$528,"Expense")+SUMIFS('Mar 2026'!$J$29:$J$528,'Mar 2026'!$E$29:$E$528,$A30,'Mar 2026'!$I$29:$I$528,"Expense")+SUMIFS('Apr 2026'!$J$29:$J$528,'Apr 2026'!$E$29:$E$528,$A30,'Apr 2026'!$I$29:$I$528,"Expense")+SUMIFS('May 2026'!$J$29:$J$528,'May 2026'!$E$29:$E$528,$A30,'May 2026'!$I$29:$I$528,"Expense")+SUMIFS('Jun 2026'!$J$29:$J$528,'Jun 2026'!$E$29:$E$528,$A30,'Jun 2026'!$I$29:$I$528,"Expense")+SUMIFS('Jul 2026'!$J$29:$J$528,'Jul 2026'!$E$29:$E$528,$A30,'Jul 2026'!$I$29:$I$528,"Expense")+SUMIFS('Aug 2026'!$J$29:$J$528,'Aug 2026'!$E$29:$E$528,$A30,'Aug 2026'!$I$29:$I$528,"Expense")+SUMIFS('Sep 2026'!$J$29:$J$528,'Sep 2026'!$E$29:$E$528,$A30,'Sep 2026'!$I$29:$I$528,"Expense")+SUMIFS('Oct 2026'!$J$29:$J$528,'Oct 2026'!$E$29:$E$528,$A30,'Oct 2026'!$I$29:$I$528,"Expense")+SUMIFS('Nov 2026'!$J$29:$J$528,'Nov 2026'!$E$29:$E$528,$A30,'Nov 2026'!$I$29:$I$528,"Expense")+SUMIFS('Dec 2026'!$J$29:$J$528,'Dec 2026'!$E$29:$E$528,$A30,'Dec 2026'!$I$29:$I$528,"Expense") -> 0 | C30: =SUMIFS('Jan 2026'!$J$29:$J$528,'Jan 2026'!$E$29:$E$528,$A30,'Jan 2026'!$I$29:$I$528,"Income")+SUMIFS('Feb 2026'!$J$29:$J$528,'Feb 2026'!$E$29:$E$528,$A30,'Feb 2026'!$I$29:$I$528,"Income")+SUMIFS('Mar 2026'!$J$29:$J$528,'Mar 2026'!$E$29:$E$528,$A30,'Mar 2026'!$I$29:$I$528,"Income")+SUMIFS('Apr 2026'!$J$29:$J$528,'Apr 2026'!$E$29:$E$528,$A30,'Apr 2026'!$I$29:$I$528,"Income")+SUMIFS('May 2026'!$J$29:$J$528,'May 2026'!$E$29:$E$528,$A30,'May 2026'!$I$29:$I$528,"Income")+SUMIFS('Jun 2026'!$J$29:$J$528,'Jun 2026'!$E$29:$E$528,$A30,'Jun 2026'!$I$29:$I$528,"Income")+SUMIFS('Jul 2026'!$J$29:$J$528,'Jul 2026'!$E$29:$E$528,$A30,'Jul 2026'!$I$29:$I$528,"Income")+SUMIFS('Aug 2026'!$J$29:$J$528,'Aug 2026'!$E$29:$E$528,$A30,'Aug 2026'!$I$29:$I$528,"Income")+SUMIFS('Sep 2026'!$J$29:$J$528,'Sep 2026'!$E$29:$E$528,$A30,'Sep 2026'!$I$29:$I$528,"Income")+SUMIFS('Oct 2026'!$J$29:$J$528,'Oct 2026'!$E$29:$E$528,$A30,'Oct 2026'!$I$29:$I$528,"Income")+SUMIFS('Nov 2026'!$J$29:$J$528,'Nov 2026'!$E$29:$E$528,$A30,'Nov 2026'!$I$29:$I$528,"Income")+SUMIFS('Dec 2026'!$J$29:$J$528,'Dec 2026'!$E$29:$E$528,$A30,'Dec 2026'!$I$29:$I$528,"Income") -> 0 | D30: =SUMIFS('Jan 2026'!$J$29:$J$528,'Jan 2026'!$E$29:$E$528,$A30,'Jan 2026'!$I$29:$I$528,"Opening Balance")+SUMIFS('Feb 2026'!$J$29:$J$528,'Feb 2026'!$E$29:$E$528,$A30,'Feb 2026'!$I$29:$I$528,"Opening Balance")+SUMIFS('Mar 2026'!$J$29:$J$528,'Mar 2026'!$E$29:$E$528,$A30,'Mar 2026'!$I$29:$I$528,"Opening Balance")+SUMIFS('Apr 2026'!$J$29:$J$528,'Apr 2026'!$E$29:$E$528,$A30,'Apr 2026'!$I$29:$I$528,"Opening Balance")+SUMIFS('May 2026'!$J$29:$J$528,'May 2026'!$E$29:$E$528,$A30,'May 2026'!$I$29:$I$528,"Opening Balance")+SUMIFS('Jun 2026'!$J$29:$J$528,'Jun 2026'!$E$29:$E$528,$A30,'Jun 2026'!$I$29:$I$528,"Opening Balance")+SUMIFS('Jul 2026'!$J$29:$J$528,'Jul 2026'!$E$29:$E$528,$A30,'Jul 2026'!$I$29:$I$528,"Opening Balance")+SUMIFS('Aug 2026'!$J$29:$J$528,'Aug 2026'!$E$29:$E$528,$A30,'Aug 2026'!$I$29:$I$528,"Opening Balance")+SUMIFS('Sep 2026'!$J$29:$J$528,'Sep 2026'!$E$29:$E$528,$A30,'Sep 2026'!$I$29:$I$528,"Opening Balance")+SUMIFS('Oct 2026'!$J$29:$J$528,'Oct 2026'!$E$29:$E$528,$A30,'Oct 2026'!$I$29:$I$528,"Opening Balance")+SUMIFS('Nov 2026'!$J$29:$J$528,'Nov 2026'!$E$29:$E$528,$A30,'Nov 2026'!$I$29:$I$528,"Opening Balance")+SUMIFS('Dec 2026'!$J$29:$J$528,'Dec 2026'!$E$29:$E$528,$A30,'Dec 2026'!$I$29:$I$528,"Opening Balance") -> 0 | E30: =C30+D30-B30 -> 0
A31: Personal Care | B31: =SUMIFS('Jan 2026'!$J$29:$J$528,'Jan 2026'!$E$29:$E$528,$A31,'Jan 2026'!$I$29:$I$528,"Expense")+SUMIFS('Feb 2026'!$J$29:$J$528,'Feb 2026'!$E$29:$E$528,$A31,'Feb 2026'!$I$29:$I$528,"Expense")+SUMIFS('Mar 2026'!$J$29:$J$528,'Mar 2026'!$E$29:$E$528,$A31,'Mar 2026'!$I$29:$I$528,"Expense")+SUMIFS('Apr 2026'!$J$29:$J$528,'Apr 2026'!$E$29:$E$528,$A31,'Apr 2026'!$I$29:$I$528,"Expense")+SUMIFS('May 2026'!$J$29:$J$528,'May 2026'!$E$29:$E$528,$A31,'May 2026'!$I$29:$I$528,"Expense")+SUMIFS('Jun 2026'!$J$29:$J$528,'Jun 2026'!$E$29:$E$528,$A31,'Jun 2026'!$I$29:$I$528,"Expense")+SUMIFS('Jul 2026'!$J$29:$J$528,'Jul 2026'!$E$29:$E$528,$A31,'Jul 2026'!$I$29:$I$528,"Expense")+SUMIFS('Aug 2026'!$J$29:$J$528,'Aug 2026'!$E$29:$E$528,$A31,'Aug 2026'!$I$29:$I$528,"Expense")+SUMIFS('Sep 2026'!$J$29:$J$528,'Sep 2026'!$E$29:$E$528,$A31,'Sep 2026'!$I$29:$I$528,"Expense")+SUMIFS('Oct 2026'!$J$29:$J$528,'Oct 2026'!$E$29:$E$528,$A31,'Oct 2026'!$I$29:$I$528,"Expense")+SUMIFS('Nov 2026'!$J$29:$J$528,'Nov 2026'!$E$29:$E$528,$A31,'Nov 2026'!$I$29:$I$528,"Expense")+SUMIFS('Dec 2026'!$J$29:$J$528,'Dec 2026'!$E$29:$E$528,$A31,'Dec 2026'!$I$29:$I$528,"Expense") -> 0 | C31: =SUMIFS('Jan 2026'!$J$29:$J$528,'Jan 2026'!$E$29:$E$528,$A31,'Jan 2026'!$I$29:$I$528,"Income")+SUMIFS('Feb 2026'!$J$29:$J$528,'Feb 2026'!$E$29:$E$528,$A31,'Feb 2026'!$I$29:$I$528,"Income")+SUMIFS('Mar 2026'!$J$29:$J$528,'Mar 2026'!$E$29:$E$528,$A31,'Mar 2026'!$I$29:$I$528,"Income")+SUMIFS('Apr 2026'!$J$29:$J$528,'Apr 2026'!$E$29:$E$528,$A31,'Apr 2026'!$I$29:$I$528,"Income")+SUMIFS('May 2026'!$J$29:$J$528,'May 2026'!$E$29:$E$528,$A31,'May 2026'!$I$29:$I$528,"Income")+SUMIFS('Jun 2026'!$J$29:$J$528,'Jun 2026'!$E$29:$E$528,$A31,'Jun 2026'!$I$29:$I$528,"Income")+SUMIFS('Jul 2026'!$J$29:$J$528,'Jul 2026'!$E$29:$E$528,$A31,'Jul 2026'!$I$29:$I$528,"Income")+SUMIFS('Aug 2026'!$J$29:$J$528,'Aug 2026'!$E$29:$E$528,$A31,'Aug 2026'!$I$29:$I$528,"Income")+SUMIFS('Sep 2026'!$J$29:$J$528,'Sep 2026'!$E$29:$E$528,$A31,'Sep 2026'!$I$29:$I$528,"Income")+SUMIFS('Oct 2026'!$J$29:$J$528,'Oct 2026'!$E$29:$E$528,$A31,'Oct 2026'!$I$29:$I$528,"Income")+SUMIFS('Nov 2026'!$J$29:$J$528,'Nov 2026'!$E$29:$E$528,$A31,'Nov 2026'!$I$29:$I$528,"Income")+SUMIFS('Dec 2026'!$J$29:$J$528,'Dec 2026'!$E$29:$E$528,$A31,'Dec 2026'!$I$29:$I$528,"Income") -> 0 | D31: =SUMIFS('Jan 2026'!$J$29:$J$528,'Jan 2026'!$E$29:$E$528,$A31,'Jan 2026'!$I$29:$I$528,"Opening Balance")+SUMIFS('Feb 2026'!$J$29:$J$528,'Feb 2026'!$E$29:$E$528,$A31,'Feb 2026'!$I$29:$I$528,"Opening Balance")+SUMIFS('Mar 2026'!$J$29:$J$528,'Mar 2026'!$E$29:$E$528,$A31,'Mar 2026'!$I$29:$I$528,"Opening Balance")+SUMIFS('Apr 2026'!$J$29:$J$528,'Apr 2026'!$E$29:$E$528,$A31,'Apr 2026'!$I$29:$I$528,"Opening Balance")+SUMIFS('May 2026'!$J$29:$J$528,'May 2026'!$E$29:$E$528,$A31,'May 2026'!$I$29:$I$528,"Opening Balance")+SUMIFS('Jun 2026'!$J$29:$J$528,'Jun 2026'!$E$29:$E$528,$A31,'Jun 2026'!$I$29:$I$528,"Opening Balance")+SUMIFS('Jul 2026'!$J$29:$J$528,'Jul 2026'!$E$29:$E$528,$A31,'Jul 2026'!$I$29:$I$528,"Opening Balance")+SUMIFS('Aug 2026'!$J$29:$J$528,'Aug 2026'!$E$29:$E$528,$A31,'Aug 2026'!$I$29:$I$528,"Opening Balance")+SUMIFS('Sep 2026'!$J$29:$J$528,'Sep 2026'!$E$29:$E$528,$A31,'Sep 2026'!$I$29:$I$528,"Opening Balance")+SUMIFS('Oct 2026'!$J$29:$J$528,'Oct 2026'!$E$29:$E$528,$A31,'Oct 2026'!$I$29:$I$528,"Opening Balance")+SUMIFS('Nov 2026'!$J$29:$J$528,'Nov 2026'!$E$29:$E$528,$A31,'Nov 2026'!$I$29:$I$528,"Opening Balance")+SUMIFS('Dec 2026'!$J$29:$J$528,'Dec 2026'!$E$29:$E$528,$A31,'Dec 2026'!$I$29:$I$528,"Opening Balance") -> 0 | E31: =C31+D31-B31 -> 0
A32: Shopping | B32: =SUMIFS('Jan 2026'!$J$29:$J$528,'Jan 2026'!$E$29:$E$528,$A32,'Jan 2026'!$I$29:$I$528,"Expense")+SUMIFS('Feb 2026'!$J$29:$J$528,'Feb 2026'!$E$29:$E$528,$A32,'Feb 2026'!$I$29:$I$528,"Expense")+SUMIFS('Mar 2026'!$J$29:$J$528,'Mar 2026'!$E$29:$E$528,$A32,'Mar 2026'!$I$29:$I$528,"Expense")+SUMIFS('Apr 2026'!$J$29:$J$528,'Apr 2026'!$E$29:$E$528,$A32,'Apr 2026'!$I$29:$I$528,"Expense")+SUMIFS('May 2026'!$J$29:$J$528,'May 2026'!$E$29:$E$528,$A32,'May 2026'!$I$29:$I$528,"Expense")+SUMIFS('Jun 2026'!$J$29:$J$528,'Jun 2026'!$E$29:$E$528,$A32,'Jun 2026'!$I$29:$I$528,"Expense")+SUMIFS('Jul 2026'!$J$29:$J$528,'Jul 2026'!$E$29:$E$528,$A32,'Jul 2026'!$I$29:$I$528,"Expense")+SUMIFS('Aug 2026'!$J$29:$J$528,'Aug 2026'!$E$29:$E$528,$A32,'Aug 2026'!$I$29:$I$528,"Expense")+SUMIFS('Sep 2026'!$J$29:$J$528,'Sep 2026'!$E$29:$E$528,$A32,'Sep 2026'!$I$29:$I$528,"Expense")+SUMIFS('Oct 2026'!$J$29:$J$528,'Oct 2026'!$E$29:$E$528,$A32,'Oct 2026'!$I$29:$I$528,"Expense")+SUMIFS('Nov 2026'!$J$29:$J$528,'Nov 2026'!$E$29:$E$528,$A32,'Nov 2026'!$I$29:$I$528,"Expense")+SUMIFS('Dec 2026'!$J$29:$J$528,'Dec 2026'!$E$29:$E$528,$A32,'Dec 2026'!$I$29:$I$528,"Expense") -> 521.78 | C32: =SUMIFS('Jan 2026'!$J$29:$J$528,'Jan 2026'!$E$29:$E$528,$A32,'Jan 2026'!$I$29:$I$528,"Income")+SUMIFS('Feb 2026'!$J$29:$J$528,'Feb 2026'!$E$29:$E$528,$A32,'Feb 2026'!$I$29:$I$528,"Income")+SUMIFS('Mar 2026'!$J$29:$J$528,'Mar 2026'!$E$29:$E$528,$A32,'Mar 2026'!$I$29:$I$528,"Income")+SUMIFS('Apr 2026'!$J$29:$J$528,'Apr 2026'!$E$29:$E$528,$A32,'Apr 2026'!$I$29:$I$528,"Income")+SUMIFS('May 2026'!$J$29:$J$528,'May 2026'!$E$29:$E$528,$A32,'May 2026'!$I$29:$I$528,"Income")+SUMIFS('Jun 2026'!$J$29:$J$528,'Jun 2026'!$E$29:$E$528,$A32,'Jun 2026'!$I$29:$I$528,"Income")+SUMIFS('Jul 2026'!$J$29:$J$528,'Jul 2026'!$E$29:$E$528,$A32,'Jul 2026'!$I$29:$I$528,"Income")+SUMIFS('Aug 2026'!$J$29:$J$528,'Aug 2026'!$E$29:$E$528,$A32,'Aug 2026'!$I$29:$I$528,"Income")+SUMIFS('Sep 2026'!$J$29:$J$528,'Sep 2026'!$E$29:$E$528,$A32,'Sep 2026'!$I$29:$I$528,"Income")+SUMIFS('Oct 2026'!$J$29:$J$528,'Oct 2026'!$E$29:$E$528,$A32,'Oct 2026'!$I$29:$I$528,"Income")+SUMIFS('Nov 2026'!$J$29:$J$528,'Nov 2026'!$E$29:$E$528,$A32,'Nov 2026'!$I$29:$I$528,"Income")+SUMIFS('Dec 2026'!$J$29:$J$528,'Dec 2026'!$E$29:$E$528,$A32,'Dec 2026'!$I$29:$I$528,"Income") -> 0 | D32: =SUMIFS('Jan 2026'!$J$29:$J$528,'Jan 2026'!$E$29:$E$528,$A32,'Jan 2026'!$I$29:$I$528,"Opening Balance")+SUMIFS('Feb 2026'!$J$29:$J$528,'Feb 2026'!$E$29:$E$528,$A32,'Feb 2026'!$I$29:$I$528,"Opening Balance")+SUMIFS('Mar 2026'!$J$29:$J$528,'Mar 2026'!$E$29:$E$528,$A32,'Mar 2026'!$I$29:$I$528,"Opening Balance")+SUMIFS('Apr 2026'!$J$29:$J$528,'Apr 2026'!$E$29:$E$528,$A32,'Apr 2026'!$I$29:$I$528,"Opening Balance")+SUMIFS('May 2026'!$J$29:$J$528,'May 2026'!$E$29:$E$528,$A32,'May 2026'!$I$29:$I$528,"Opening Balance")+SUMIFS('Jun 2026'!$J$29:$J$528,'Jun 2026'!$E$29:$E$528,$A32,'Jun 2026'!$I$29:$I$528,"Opening Balance")+SUMIFS('Jul 2026'!$J$29:$J$528,'Jul 2026'!$E$29:$E$528,$A32,'Jul 2026'!$I$29:$I$528,"Opening Balance")+SUMIFS('Aug 2026'!$J$29:$J$528,'Aug 2026'!$E$29:$E$528,$A32,'Aug 2026'!$I$29:$I$528,"Opening Balance")+SUMIFS('Sep 2026'!$J$29:$J$528,'Sep 2026'!$E$29:$E$528,$A32,'Sep 2026'!$I$29:$I$528,"Opening Balance")+SUMIFS('Oct 2026'!$J$29:$J$528,'Oct 2026'!$E$29:$E$528,$A32,'Oct 2026'!$I$29:$I$528,"Opening Balance")+SUMIFS('Nov 2026'!$J$29:$J$528,'Nov 2026'!$E$29:$E$528,$A32,'Nov 2026'!$I$29:$I$528,"Opening Balance")+SUMIFS('Dec 2026'!$J$29:$J$528,'Dec 2026'!$E$29:$E$528,$A32,'Dec 2026'!$I$29:$I$528,"Opening Balance") -> 0 | E32: =C32+D32-B32 -> -521.78
A33: Entertainment | B33: =SUMIFS('Jan 2026'!$J$29:$J$528,'Jan 2026'!$E$29:$E$528,$A33,'Jan 2026'!$I$29:$I$528,"Expense")+SUMIFS('Feb 2026'!$J$29:$J$528,'Feb 2026'!$E$29:$E$528,$A33,'Feb 2026'!$I$29:$I$528,"Expense")+SUMIFS('Mar 2026'!$J$29:$J$528,'Mar 2026'!$E$29:$E$528,$A33,'Mar 2026'!$I$29:$I$528,"Expense")+SUMIFS('Apr 2026'!$J$29:$J$528,'Apr 2026'!$E$29:$E$528,$A33,'Apr 2026'!$I$29:$I$528,"Expense")+SUMIFS('May 2026'!$J$29:$J$528,'May 2026'!$E$29:$E$528,$A33,'May 2026'!$I$29:$I$528,"Expense")+SUMIFS('Jun 2026'!$J$29:$J$528,'Jun 2026'!$E$29:$E$528,$A33,'Jun 2026'!$I$29:$I$528,"Expense")+SUMIFS('Jul 2026'!$J$29:$J$528,'Jul 2026'!$E$29:$E$528,$A33,'Jul 2026'!$I$29:$I$528,"Expense")+SUMIFS('Aug 2026'!$J$29:$J$528,'Aug 2026'!$E$29:$E$528,$A33,'Aug 2026'!$I$29:$I$528,"Expense")+SUMIFS('Sep 2026'!$J$29:$J$528,'Sep 2026'!$E$29:$E$528,$A33,'Sep 2026'!$I$29:$I$528,"Expense")+SUMIFS('Oct 2026'!$J$29:$J$528,'Oct 2026'!$E$29:$E$528,$A33,'Oct 2026'!$I$29:$I$528,"Expense")+SUMIFS('Nov 2026'!$J$29:$J$528,'Nov 2026'!$E$29:$E$528,$A33,'Nov 2026'!$I$29:$I$528,"Expense")+SUMIFS('Dec 2026'!$J$29:$J$528,'Dec 2026'!$E$29:$E$528,$A33,'Dec 2026'!$I$29:$I$528,"Expense") -> 543.59 | C33: =SUMIFS('Jan 2026'!$J$29:$J$528,'Jan 2026'!$E$29:$E$528,$A33,'Jan 2026'!$I$29:$I$528,"Income")+SUMIFS('Feb 2026'!$J$29:$J$528,'Feb 2026'!$E$29:$E$528,$A33,'Feb 2026'!$I$29:$I$528,"Income")+SUMIFS('Mar 2026'!$J$29:$J$528,'Mar 2026'!$E$29:$E$528,$A33,'Mar 2026'!$I$29:$I$528,"Income")+SUMIFS('Apr 2026'!$J$29:$J$528,'Apr 2026'!$E$29:$E$528,$A33,'Apr 2026'!$I$29:$I$528,"Income")+SUMIFS('May 2026'!$J$29:$J$528,'May 2026'!$E$29:$E$528,$A33,'May 2026'!$I$29:$I$528,"Income")+SUMIFS('Jun 2026'!$J$29:$J$528,'Jun 2026'!$E$29:$E$528,$A33,'Jun 2026'!$I$29:$I$528,"Income")+SUMIFS('Jul 2026'!$J$29:$J$528,'Jul 2026'!$E$29:$E$528,$A33,'Jul 2026'!$I$29:$I$528,"Income")+SUMIFS('Aug 2026'!$J$29:$J$528,'Aug 2026'!$E$29:$E$528,$A33,'Aug 2026'!$I$29:$I$528,"Income")+SUMIFS('Sep 2026'!$J$29:$J$528,'Sep 2026'!$E$29:$E$528,$A33,'Sep 2026'!$I$29:$I$528,"Income")+SUMIFS('Oct 2026'!$J$29:$J$528,'Oct 2026'!$E$29:$E$528,$A33,'Oct 2026'!$I$29:$I$528,"Income")+SUMIFS('Nov 2026'!$J$29:$J$528,'Nov 2026'!$E$29:$E$528,$A33,'Nov 2026'!$I$29:$I$528,"Income")+SUMIFS('Dec 2026'!$J$29:$J$528,'Dec 2026'!$E$29:$E$528,$A33,'Dec 2026'!$I$29:$I$528,"Income") -> 0 | D33: =SUMIFS('Jan 2026'!$J$29:$J$528,'Jan 2026'!$E$29:$E$528,$A33,'Jan 2026'!$I$29:$I$528,"Opening Balance")+SUMIFS('Feb 2026'!$J$29:$J$528,'Feb 2026'!$E$29:$E$528,$A33,'Feb 2026'!$I$29:$I$528,"Opening Balance")+SUMIFS('Mar 2026'!$J$29:$J$528,'Mar 2026'!$E$29:$E$528,$A33,'Mar 2026'!$I$29:$I$528,"Opening Balance")+SUMIFS('Apr 2026'!$J$29:$J$528,'Apr 2026'!$E$29:$E$528,$A33,'Apr 2026'!$I$29:$I$528,"Opening Balance")+SUMIFS('May 2026'!$J$29:$J$528,'May 2026'!$E$29:$E$528,$A33,'May 2026'!$I$29:$I$528,"Opening Balance")+SUMIFS('Jun 2026'!$J$29:$J$528,'Jun 2026'!$E$29:$E$528,$A33,'Jun 2026'!$I$29:$I$528,"Opening Balance")+SUMIFS('Jul 2026'!$J$29:$J$528,'Jul 2026'!$E$29:$E$528,$A33,'Jul 2026'!$I$29:$I$528,"Opening Balance")+SUMIFS('Aug 2026'!$J$29:$J$528,'Aug 2026'!$E$29:$E$528,$A33,'Aug 2026'!$I$29:$I$528,"Opening Balance")+SUMIFS('Sep 2026'!$J$29:$J$528,'Sep 2026'!$E$29:$E$528,$A33,'Sep 2026'!$I$29:$I$528,"Opening Balance")+SUMIFS('Oct 2026'!$J$29:$J$528,'Oct 2026'!$E$29:$E$528,$A33,'Oct 2026'!$I$29:$I$528,"Opening Balance")+SUMIFS('Nov 2026'!$J$29:$J$528,'Nov 2026'!$E$29:$E$528,$A33,'Nov 2026'!$I$29:$I$528,"Opening Balance")+SUMIFS('Dec 2026'!$J$29:$J$528,'Dec 2026'!$E$29:$E$528,$A33,'Dec 2026'!$I$29:$I$528,"Opening Balance") -> 0 | E33: =C33+D33-B33 -> -543.59
... A42: Other | B42: =SUMIFS('Jan 2026'!$J$29:$J$528,'Jan 2026'!$E$29:$E$528,$A42,'Jan 2026'!$I$29:$I$528,"Expense")+SUMIFS('Feb 2026'!$J$29:$J$528,'Feb 2026'!$E$29:$E$528,$A42,'Feb 2026'!$I$29:$I$528,"Expense")+SUMIFS('Mar 2026'!$J$29:$J$528,'Mar 2026'!$E$29:$E$528,$A42,'Mar 2026'!$I$29:$I$528,"Expense")+SUMIFS('Apr 2026'!$J$29:$J$528,'Apr 2026'!$E$29:$E$528,$A42,'Apr 2026'!$I$29:$I$528,"Expense")+SUMIFS('May 2026'!$J$29:$J$528,'May 2026'!$E$29:$E$528,$A42,'May 2026'!$I$29:$I$528,"Expense")+SUMIFS('Jun 2026'!$J$29:$J$528,'Jun 2026'!$E$29:$E$528,$A42,'Jun 2026'!$I$29:$I$528,"Expense")+SUMIFS('Jul 2026'!$J$29:$J$528,'Jul 2026'!$E$29:$E$528,$A42,'Jul 2026'!$I$29:$I$528,"Expense")+SUMIFS('Aug 2026'!$J$29:$J$528,'Aug 2026'!$E$29:$E$528,$A42,'Aug 2026'!$I$29:$I$528,"Expense")+SUMIFS('Sep 2026'!$J$29:$J$528,'Sep 2026'!$E$29:$E$528,$A42,'Sep 2026'!$I$29:$I$528,"Expense")+SUMIFS('Oct 2026'!$J$29:$J$528,'Oct 2026'!$E$29:$E$528,$A42,'Oct 2026'!$I$29:$I$528,"Expense")+SUMIFS('Nov 2026'!$J$29:$J$528,'Nov 2026'!$E$29:$E$528,$A42,'Nov 2026'!$I$29:$I$528,"Expense")+SUMIFS('Dec 2026'!$J$29:$J$528,'Dec 2026'!$E$29:$E$528,$A42,'Dec 2026'!$I$29:$I$528,"Expense") -> 0 | C42: =SUMIFS('Jan 2026'!$J$29:$J$528,'Jan 2026'!$E$29:$E$528,$A42,'Jan 2026'!$I$29:$I$528,"Income")+SUMIFS('Feb 2026'!$J$29:$J$528,'Feb 2026'!$E$29:$E$528,$A42,'Feb 2026'!$I$29:$I$528,"Income")+SUMIFS('Mar 2026'!$J$29:$J$528,'Mar 2026'!$E$29:$E$528,$A42,'Mar 2026'!$I$29:$I$528,"Income")+SUMIFS('Apr 2026'!$J$29:$J$528,'Apr 2026'!$E$29:$E$528,$A42,'Apr 2026'!$I$29:$I$528,"Income")+SUMIFS('May 2026'!$J$29:$J$528,'May 2026'!$E$29:$E$528,$A42,'May 2026'!$I$29:$I$528,"Income")+SUMIFS('Jun 2026'!$J$29:$J$528,'Jun 2026'!$E$29:$E$528,$A42,'Jun 2026'!$I$29:$I$528,"Income")+SUMIFS('Jul 2026'!$J$29:$J$528,'Jul 2026'!$E$29:$E$528,$A42,'Jul 2026'!$I$29:$I$528,"Income")+SUMIFS('Aug 2026'!$J$29:$J$528,'Aug 2026'!$E$29:$E$528,$A42,'Aug 2026'!$I$29:$I$528,"Income")+SUMIFS('Sep 2026'!$J$29:$J$528,'Sep 2026'!$E$29:$E$528,$A42,'Sep 2026'!$I$29:$I$528,"Income")+SUMIFS('Oct 2026'!$J$29:$J$528,'Oct 2026'!$E$29:$E$528,$A42,'Oct 2026'!$I$29:$I$528,"Income")+SUMIFS('Nov 2026'!$J$29:$J$528,'Nov 2026'!$E$29:$E$528,$A42,'Nov 2026'!$I$29:$I$528,"Income")+SUMIFS('Dec 2026'!$J$29:$J$528,'Dec 2026'!$E$29:$E$528,$A42,'Dec 2026'!$I$29:$I$528,"Income") -> 0 | D42: =SUMIFS('Jan 2026'!$J$29:$J$528,'Jan 2026'!$E$29:$E$528,$A42,'Jan 2026'!$I$29:$I$528,"Opening Balance")+SUMIFS('Feb 2026'!$J$29:$J$528,'Feb 2026'!$E$29:$E$528,$A42,'Feb 2026'!$I$29:$I$528,"Opening Balance")+SUMIFS('Mar 2026'!$J$29:$J$528,'Mar 2026'!$E$29:$E$528,$A42,'Mar 2026'!$I$29:$I$528,"Opening Balance")+SUMIFS('Apr 2026'!$J$29:$J$528,'Apr 2026'!$E$29:$E$528,$A42,'Apr 2026'!$I$29:$I$528,"Opening Balance")+SUMIFS('May 2026'!$J$29:$J$528,'May 2026'!$E$29:$E$528,$A42,'May 2026'!$I$29:$I$528,"Opening Balance")+SUMIFS('Jun 2026'!$J$29:$J$528,'Jun 2026'!$E$29:$E$528,$A42,'Jun 2026'!$I$29:$I$528,"Opening Balance")+SUMIFS('Jul 2026'!$J$29:$J$528,'Jul 2026'!$E$29:$E$528,$A42,'Jul 2026'!$I$29:$I$528,"Opening Balance")+SUMIFS('Aug 2026'!$J$29:$J$528,'Aug 2026'!$E$29:$E$528,$A42,'Aug 2026'!$I$29:$I$528,"Opening Balance")+SUMIFS('Sep 2026'!$J$29:$J$528,'Sep 2026'!$E$29:$E$528,$A42,'Sep 2026'!$I$29:$I$528,"Opening Balance")+SUMIFS('Oct 2026'!$J$29:$J$528,'Oct 2026'!$E$29:$E$528,$A42,'Oct 2026'!$I$29:$I$528,"Opening Balance")+SUMIFS('Nov 2026'!$J$29:$J$528,'Nov 2026'!$E$29:$E$528,$A42,'Nov 2026'!$I$29:$I$528,"Opening Balance")+SUMIFS('Dec 2026'!$J$29:$J$528,'Dec 2026'!$E$29:$E$528,$A42,'Dec 2026'!$I$29:$I$528,"Opening Balance") -> 0 | E42: =C42+D42-B42 -> 0

Sheet Jan 2026
A1: January 2026 Ledger
A2: Use positive amounts. Choose Type to classify each transaction.
A4: Month Summary | D4: Category Summary | H4: Weekly Summary
A5: Total Income | B5: =SUMIFS($J$29:$J$528,$I$29:$I$528,"Income") | D5: Category | E5: Expenses | F5: Income | G5: Existing Savings | H5: Week | I5: Expenses | J5: Income | K5: Net
A6: Total Expenses | B6: =SUMIFS($J$29:$J$528,$I$29:$I$528,"Expense") | D6: Housing | E6: =SUMIFS($J$29:$J$528,$E$29:$E$528,$D6,$I$29:$I$528,"Expense") | F6: =SUMIFS($J$29:$J$528,$E$29:$E$528,$D6,$I$29:$I$528,"Income") | G6: =SUMIFS($J$29:$J$528,$E$29:$E$528,$D6,$I$29:$I$528,"Opening Balance") | H6: Week 1 | I6: =SUMIFS($J$29:$J$528,$B$29:$B$528,1,$I$29:$I$528,"Expense",$F$29:$F$528,"<>Rent") | J6: =SUMIFS($J$29:$J$528,$B$29:$B$528,1,$I$29:$I$528,"Income") | K6: =J6-I6
A7: Existing Savings | B7: =SUMIFS($J$29:$J$528,$I$29:$I$528,"Opening Balance") | D7: Utilities | E7: =SUMIFS($J$29:$J$528,$E$29:$E$528,$D7,$I$29:$I$528,"Expense") | F7: =SUMIFS($J$29:$J$528,$E$29:$E$528,$D7,$I$29:$I$528,"Income") | G7: =SUMIFS($J$29:$J$528,$E$29:$E$528,$D7,$I$29:$I$528,"Opening Balance") | H7: Week 2 | I7: =SUMIFS($J$29:$J$528,$B$29:$B$528,2,$I$29:$I$528,"Expense",$F$29:$F$528,"<>Rent") | J7: =SUMIFS($J$29:$J$528,$B$29:$B$528,2,$I$29:$I$528,"Income") | K7: =J7-I7
A8: Transfers | B8: =SUMIFS($J$29:$J$528,$I$29:$I$528,"Transfer") | D8: Groceries | E8: =SUMIFS($J$29:$J$528,$E$29:$E$528,$D8,$I$29:$I$528,"Expense") | F8: =SUMIFS($J$29:$J$528,$E$29:$E$528,$D8,$I$29:$I$528,"Income") | G8: =SUMIFS($J$29:$J$528,$E$29:$E$528,$D8,$I$29:$I$528,"Opening Balance") | H8: Week 3 | I8: =SUMIFS($J$29:$J$528,$B$29:$B$528,3,$I$29:$I$528,"Expense",$F$29:$F$528,"<>Rent") | J8: =SUMIFS($J$29:$J$528,$B$29:$B$528,3,$I$29:$I$528,"Income") | K8: =J8-I8
A9: Net Cash Flow | B9: =B5-B6 | D9: Dining | E9: =SUMIFS($J$29:$J$528,$E$29:$E$528,$D9,$I$29:$I$528,"Expense") | F9: =SUMIFS($J$29:$J$528,$E$29:$E$528,$D9,$I$29:$I$528,"Income") | G9: =SUMIFS($J$29:$J$528,$E$29:$E$528,$D9,$I$29:$I$528,"Opening Balance") | H9: Week 4 | I9: =SUMIFS($J$29:$J$528,$B$29:$B$528,4,$I$29:$I$528,"Expense",$F$29:$F$528,"<>Rent") | J9: =SUMIFS($J$29:$J$528,$B$29:$B$528,4,$I$29:$I$528,"Income") | K9: =J9-I9
D10: Transportation | E10: =SUMIFS($J$29:$J$528,$E$29:$E$528,$D10,$I$29:$I$528,"Expense") | F10: =SUMIFS($J$29:$J$528,$E$29:$E$528,$D10,$I$29:$I$528,"Income") | G10: =SUMIFS($J$29:$J$528,$E$29:$E$528,$D10,$I$29:$I$528,"Opening Balance") | H10: Week 5 | I10: =SUMIFS($J$29:$J$528,$B$29:$B$528,5,$I$29:$I$528,"Expense",$F$29:$F$528,"<>Rent") | J10: =SUMIFS($J$29:$J$528,$B$29:$B$528,5,$I$29:$I$528,"Income") | K10: =J10-I10
D11: Health & Medical | E11: =SUMIFS($J$29:$J$528,$E$29:$E$528,$D11,$I$29:$I$528,"Expense") | F11: =SUMIFS($J$29:$J$528,$E$29:$E$528,$D11,$I$29:$I$528,"Income") | G11: =SUMIFS($J$29:$J$528,$E$29:$E$528,$D11,$I$29:$I$528,"Opening Balance")
D12: Insurance | E12: =SUMIFS($J$29:$J$528,$E$29:$E$528,$D12,$I$29:$I$528,"Expense") | F12: =SUMIFS($J$29:$J$528,$E$29:$E$528,$D12,$I$29:$I$528,"Income") | G12: =SUMIFS($J$29:$J$528,$E$29:$E$528,$D12,$I$29:$I$528,"Opening Balance")
D13: Debt Payments | E13: =SUMIFS($J$29:$J$528,$E$29:$E$528,$D13,$I$29:$I$528,"Expense") | F13: =SUMIFS($J$29:$J$528,$E$29:$E$528,$D13,$I$29:$I$528,"Income") | G13: =SUMIFS($J$29:$J$528,$E$29:$E$528,$D13,$I$29:$I$528,"Opening Balance")
D14: Savings & Investments | E14: =SUMIFS($J$29:$J$528,$E$29:$E$528,$D14,$I$29:$I$528,"Expense") | F14: =SUMIFS($J$29:$J$528,$E$29:$E$528,$D14,$I$29:$I$528,"Income") | G14: =SUMIFS($J$29:$J$528,$E$29:$E$528,$D14,$I$29:$I$528,"Opening Balance")
D15: Personal Care | E15: =SUMIFS($J$29:$J$528,$E$29:$E$528,$D15,$I$29:$I$528,"Expense") | F15: =SUMIFS($J$29:$J$528,$E$29:$E$528,$D15,$I$29:$I$528,"Income") | G15: =SUMIFS($J$29:$J$528,$E$29:$E$528,$D15,$I$29:$I$528,"Opening Balance")
D16: Shopping | E16: =SUMIFS($J$29:$J$528,$E$29:$E$528,$D16,$I$29:$I$528,"Expense") | F16: =SUMIFS($J$29:$J$528,$E$29:$E$528,$D16,$I$29:$I$528,"Income") | G16: =SUMIFS($J$29:$J$528,$E$29:$E$528,$D16,$I$29:$I$528,"Opening Balance")
D17: Entertainment | E17: =SUMIFS($J$29:$J$528,$E$29:$E$528,$D17,$I$29:$I$528,"Expense") | F17: =SUMIFS($J$29:$J$528,$E$29:$E$528,$D17,$I$29:$I$528,"Income") | G17: =SUMIFS($J$29:$J$528,$E$29:$E$528,$D17,$I$29:$I$528,"Opening Balance")
D18: Travel | E18: =SUMIFS($J$29:$J$528,$E$29:$E$528,$D18,$I$29:$I$528,"Expense") | F18: =SUMIFS($J$29:$J$528,$E$29:$E$528,$D18,$I$29:$I$528,"Income") | G18: =SUMIFS($J$29:$J$528,$E$29:$E$528,$D18,$I$29:$I$528,"Opening Balance")
D19: Education | E19: =SUMIFS($J$29:$J$528,$E$29:$E$528,$D19,$I$29:$I$528,"Expense") | F19: =SUMIFS($J$29:$J$528,$E$29:$E$528,$D19,$I$29:$I$528,"Income") | G19: =SUMIFS($J$29:$J$528,$E$29:$E$528,$D19,$I$29:$I$528,"Opening Balance")
D20: Gifts & Donations | E20: =SUMIFS($J$29:$J$528,$E$29:$E$528,$D20,$I$29:$I$528,"Expense") | F20: =SUMIFS($J$29:$J$528,$E$29:$E$528,$D20,$I$29:$I$528,"Income") | G20: =SUMIFS($J$29:$J$528,$E$29:$E$528,$D20,$I$29:$I$528,"Opening Balance")
D21: Taxes | E21: =SUMIFS($J$29:$J$528,$E$29:$E$528,$D21,$I$29:$I$528,"Expense") | F21: =SUMIFS($J$29:$J$528,$E$29:$E$528,$D21,$I$29:$I$528,"Income") | G21: =SUMIFS($J$29:$J$528,$E$29:$E$528,$D21,$I$29:$I$528,"Opening Balance")
D22: Shipping | E22: =SUMIFS($J$29:$J$528,$E$29:$E$528,$D22,$I$29:$I$528,"Expense") | F22: =SUMIFS($J$29:$J$528,$E$29:$E$528,$D22,$I$29:$I$528,"Income") | G22: =SUMIFS($J$29:$J$528,$E$29:$E$528,$D22,$I$29:$I$528,"Opening Balance")
... D26: Essentials | E26: =SUMIFS($J$29:$J$528,$E$29:$E$528,$D26,$I$29:$I$528,"Expense") | F26: =SUMIFS($J$29:$J$528,$E$29:$E$528,$D26,$I$29:$I$528,"Income") | G26: =SUMIFS($J$29:$J$528,$E$29:$E$528,$D26,$I$29:$I$528,"Opening Balance")
A27: Transactions
A28: Date | B28: Week | C28: Description | D28: Merchant | E28: Category | F28: Subcategory | G28: Account | H28: Payment Method | I28: Type | J28: Amount | K28: Notes
B29: =IF(A29="","",INT((DAY(A29)-1)/7)+1)
B30: =IF(A30="","",INT((DAY(A30)-1)/7)+1)
B31: =IF(A31="","",INT((DAY(A31)-1)/7)+1)
B32: =IF(A32="","",INT((DAY(A32)-1)/7)+1)
B33: =IF(A33="","",INT((DAY(A33)-1)/7)+1)
B34: =IF(A34="","",INT((DAY(A34)-1)/7)+1)
B35: =IF(A35="","",INT((DAY(A35)-1)/7)+1)
B36: =IF(A36="","",INT((DAY(A36)-1)/7)+1)
B37: =IF(A37="","",INT((DAY(A37)-1)/7)+1)
B38: =IF(A38="","",INT((DAY(A38)-1)/7)+1)
B39: =IF(A39="","",INT((DAY(A39)-1)/7)+1)
B40: =IF(A40="","",INT((DAY(A40)-1)/7)+1)
... B528: =IF(A528="","",INT((DAY(A528)-1)/7)+1)

Sheet Feb 2026
A1: February 2026 Ledger
A2: Use positive amounts. Choose Type to classify each transaction.
A4: Month Summary | D4: Category Summary | H4: Weekly Summary
A5: Total Income | B5: =SUMIFS($J$29:$J$528,$I$29:$I$528,"Income") | D5: Category | E5: Expenses | F5: Income | G5: Existing Savings | H5: Week | I5: Expenses | J5: Income | K5: Net
A6: Total Expenses | B6: =SUMIFS($J$29:$J$528,$I$29:$I$528,"Expense") | D6: Housing | E6: =SUMIFS($J$29:$J$528,$E$29:$E$528,$D6,$I$29:$I$528,"Expense") | F6: =SUMIFS($J$29:$J$528,$E$29:$E$528,$D6,$I$29:$I$528,"Income") | G6: =SUMIFS($J$29:$J$528,$E$29:$E$528,$D6,$I$29:$I$528,"Opening Balance") | H6: Week 1 | I6: =SUMIFS($J$29:$J$528,$B$29:$B$528,1,$I$29:$I$528,"Expense",$F$29:$F$528,"<>Rent") | J6: =SUMIFS($J$29:$J$528,$B$29:$B$528,1,$I$29:$I$528,"Income") | K6: =J6-I6
A7: Existing Savings | B7: =SUMIFS($J$29:$J$528,$I$29:$I$528,"Opening Balance") | D7: Utilities | E7: =SUMIFS($J$29:$J$528,$E$29:$E$528,$D7,$I$29:$I$528,"Expense") | F7: =SUMIFS($J$29:$J$528,$E$29:$E$528,$D7,$I$29:$I$528,"Income") | G7: =SUMIFS($J$29:$J$528,$E$29:$E$528,$D7,$I$29:$I$528,"Opening Balance") | H7: Week 2 | I7: =SUMIFS($J$29:$J$528,$B$29:$B$528,2,$I$29:$I$528,"Expense",$F$29:$F$528,"<>Rent") | J7: =SUMIFS($J$29:$J$528,$B$29:$B$528,2,$I$29:$I$528,"Income") | K7: =J7-I7
A8: Transfers | B8: =SUMIFS($J$29:$J$528,$I$29:$I$528,"Transfer") | D8: Groceries | E8: =SUMIFS($J$29:$J$528,$E$29:$E$528,$D8,$I$29:$I$528,"Expense") | F8: =SUMIFS($J$29:$J$528,$E$29:$E$528,$D8,$I$29:$I$528,"Income") | G8: =SUMIFS($J$29:$J$528,$E$29:$E$528,$D8,$I$29:$I$528,"Opening Balance") | H8: Week 3 | I8: =SUMIFS($J$29:$J$528,$B$29:$B$528,3,$I$29:$I$528,"Expense",$F$29:$F$528,"<>Rent") | J8: =SUMIFS($J$29:$J$528,$B$29:$B$528,3,$I$29:$I$528,"Income") | K8: =J8-I8
A9: Net Cash Flow | B9: =B5-B6 | D9: Dining | E9: =SUMIFS($J$29:$J$528,$E$29:$E$528,$D9,$I$29:$I$528,"Expense") | F9: =SUMIFS($J$29:$J$528,$E$29:$E$528,$D9,$I$29:$I$528,"Income") | G9: =SUMIFS($J$29:$J$528,$E$29:$E$528,$D9,$I$29:$I$528,"Opening Balance") | H9: Week 4 | I9: =SUMIFS($J$29:$J$528,$B$29:$B$528,4,$I$29:$I$528,"Expense",$F$29:$F$528,"<>Rent") | J9: =SUMIFS($J$29:$J$528,$B$29:$B$528,4,$I$29:$I$528,"Income") | K9: =J9-I9
D10: Transportation | E10: =SUMIFS($J$29:$J$528,$E$29:$E$528,$D10,$I$29:$I$528,"Expense") | F10: =SUMIFS($J$29:$J$528,$E$29:$E$528,$D10,$I$29:$I$528,"Income") | G10: =SUMIFS($J$29:$J$528,$E$29:$E$528,$D10,$I$29:$I$528,"Opening Balance") | H10: Week 5 | I10: =SUMIFS($J$29:$J$528,$B$29:$B$528,5,$I$29:$I$528,"Expense",$F$29:$F$528,"<>Rent") | J10: =SUMIFS($J$29:$J$528,$B$29:$B$528,5,$I$29:$I$528,"Income") | K10: =J10-I10
D11: Health & Medical | E11: =SUMIFS($J$29:$J$528,$E$29:$E$528,$D11,$I$29:$I$528,"Expense") | F11: =SUMIFS($J$29:$J$528,$E$29:$E$528,$D11,$I$29:$I$528,"Income") | G11: =SUMIFS($J$29:$J$528,$E$29:$E$528,$D11,$I$29:$I$528,"Opening Balance")
D12: Insurance | E12: =SUMIFS($J$29:$J$528,$E$29:$E$528,$D12,$I$29:$I$528,"Expense") | F12: =SUMIFS($J$29:$J$528,$E$29:$E$528,$D12,$I$29:$I$528,"Income") | G12: =SUMIFS($J$29:$J$528,$E$29:$E$528,$D12,$I$29:$I$528,"Opening Balance")
D13: Debt Payments | E13: =SUMIFS($J$29:$J$528,$E$29:$E$528,$D13,$I$29:$I$528,"Expense") | F13: =SUMIFS($J$29:$J$528,$E$29:$E$528,$D13,$I$29:$I$528,"Income") | G13: =SUMIFS($J$29:$J$528,$E$29:$E$528,$D13,$I$29:$I$528,"Opening Balance")
D14: Savings & Investments | E14: =SUMIFS($J$29:$J$528,$E$29:$E$528,$D14,$I$29:$I$528,"Expense") | F14: =SUMIFS($J$29:$J$528,$E$29:$E$528,$D14,$I$29:$I$528,"Income") | G14: =SUMIFS($J$29:$J$528,$E$29:$E$528,$D14,$I$29:$I$528,"Opening Balance")
D15: Personal Care | E15: =SUMIFS($J$29:$J$528,$E$29:$E$528,$D15,$I$29:$I$528,"Expense") | F15: =SUMIFS($J$29:$J$528,$E$29:$E$528,$D15,$I$29:$I$528,"Income") | G15: =SUMIFS($J$29:$J$528,$E$29:$E$528,$D15,$I$29:$I$528,"Opening Balance")
D16: Shopping | E16: =SUMIFS($J$29:$J$528,$E$29:$E$528,$D16,$I$29:$I$528,"Expense") | F16: =SUMIFS($J$29:$J$528,$E$29:$E$528,$D16,$I$29:$I$528,"Income") | G16: =SUMIFS($J$29:$J$528,$E$29:$E$528,$D16,$I$29:$I$528,"Opening Balance")
